Workbook

Sheet Step1_wo_dropout
A1: № | B1: Модель | C1: model size M | D1: n_layer | E1: n_embd | F1: n_head | G1: block_size | H1: dropout | I1: batch_size | J1: train iterations | K1: train loss | L1: val iterations | M1: val loss
A2: 1 | B2: =D2&"/"&E2&"/"&F2&"/"&G2&"/"&TEXT(H2,"0.00")&"/"&I2 -> 1/32/1/32/0.00/64 | C2: =($P$2*E2+E2*G2+D2*(12*E2^2+13*E2)+E2*$P$2)/1000000 -> 0.025568 | D2: 1 | E2: 32 | F2: 1 | G2: 32 | H2: 0 | I2: 64 | J2: 800000 | K2: 1.6392 | L2: 970000 | M2: 1.9899 | O2: vocab_size | P2: 185
A3: 2 | B3: =D3&"/"&E3&"/"&F3&"/"&G3&"/"&TEXT(H3,"0.00")&"/"&I3 -> 1/32/1/64/0.00/64 | C3: =($P$2*E3+E3*G3+D3*(12*E3^2+13*E3)+E3*$P$2)/1000000 -> 0.026592 | D3: 1 | E3: 32 | F3: 1 | G3: 64 | H3: 0 | I3: 64 | J3: 800000 | K3: 1.6274 | L3: 820000 | M3: 1.9898
A4: 3 | B4: =D4&"/"&E4&"/"&F4&"/"&G4&"/"&TEXT(H4,"0.00")&"/"&I4 -> 1/32/1/128/0.00/64 | C4: =($P$2*E4+E4*G4+D4*(12*E4^2+13*E4)+E4*$P$2)/1000000 -> 0.02864 | D4: 1 | E4: 32 | F4: 1 | G4: 128 | H4: 0 | I4: 64 | J4: 890000 | K4: 1.629 | L4: 840000 | M4: 1.999
A5: 4 | B5: =D5&"/"&E5&"/"&F5&"/"&G5&"/"&TEXT(H5,"0.00")&"/"&I5 -> 1/32/1/256/0.00/64 | C5: =($P$2*E5+E5*G5+D5*(12*E5^2+13*E5)+E5*$P$2)/1000000 -> 0.032736 | D5: 1 | E5: 32 | F5: 1 | G5: 256 | H5: 0 | I5: 64 | J5: 930000 | K5: 1.6695 | L5: 980000 | M5: 2.0392
A6: 5 | B6: =D6&"/"&E6&"/"&F6&"/"&G6&"/"&TEXT(H6,"0.00")&"/"&I6 -> 2/32/1/32/0.00/64 | C6: =($P$2*E6+E6*G6+D6*(12*E6^2+13*E6)+E6*$P$2)/1000000 -> 0.038272 | D6: 2 | E6: 32 | F6: 1 | G6: 32 | H6: 0 | I6: 64 | J6: 890000 | K6: 1.4792 | L6: 790000 | M6: 1.8494
A7: 6 | B7: =D7&"/"&E7&"/"&F7&"/"&G7&"/"&TEXT(H7,"0.00")&"/"&I7 -> 2/32/1/64/0.00/64 | C7: =($P$2*E7+E7*G7+D7*(12*E7^2+13*E7)+E7*$P$2)/1000000 -> 0.039296 | D7: 2 | E7: 32 | F7: 1 | G7: 64 | H7: 0 | I7: 64 | J7: 890000 | K7: 1.4491 | L7: 700000 | M7: 1.8496
A8: 7 | B8: =D8&"/"&E8&"/"&F8&"/"&G8&"/"&TEXT(H8,"0.00")&"/"&I8 -> 2/32/1/128/0.00/64 | C8: =($P$2*E8+E8*G8+D8*(12*E8^2+13*E8)+E8*$P$2)/1000000 -> 0.041344 | D8: 2 | E8: 32 | F8: 1 | G8: 128 | H8: 0 | I8: 64 | J8: 1000000 | K8: 1.4176 | L8: 780000 | M8: 1.818
A9: 8 | B9: =D9&"/"&E9&"/"&F9&"/"&G9&"/"&TEXT(H9,"0.00")&"/"&I9 -> 2/32/1/256/0.00/64 | C9: =($P$2*E9+E9*G9+D9*(12*E9^2+13*E9)+E9*$P$2)/1000000 -> 0.04544 | D9: 2 | E9: 32 | F9: 1 | G9: 256 | H9: 0 | I9: 64 | J9: 960000 | K9: 1.4366 | L9: 850000 | M9: 1.8479
A10: 9 | B10: =D10&"/"&E10&"/"&F10&"/"&G10&"/"&TEXT(H10,"0.00")&"/"&I10 -> 1/64/2/64/0.00/64 | C10: =($P$2*E10+E10*G10+D10*(12*E10^2+13*E10)+E10*$P$2)/1000000 -> 0.07776 | D10: 1 | E10: 64 | F10: 2 | G10: 64 | H10: 0 | I10: 64 | J10: 530000 | K10: 1.379 | L10: 530000 | M10: 1.815
A11: 10 | B11: =D11&"/"&E11&"/"&F11&"/"&G11&"/"&TEXT(H11,"0.00")&"/"&I11 -> 1/64/2/128/0.00/64 | C11: =($P$2*E11+E11*G11+D11*(12*E11^2+13*E11)+E11*$P$2)/1000000 -> 0.081856 | D11: 1 | E11: 64 | F11: 2 | G11: 128 | H11: 0 | I11: 64 | J11: 450000 | K11: 1.3693 | L11: 330000 | M11: 1.7953
A12: 11 | B12: =D12&"/"&E12&"/"&F12&"/"&G12&"/"&TEXT(H12,"0.00")&"/"&I12 -> 1/64/2/256/0.00/64 | C12: =($P$2*E12+E12*G12+D12*(12*E12^2+13*E12)+E12*$P$2)/1000000 -> 0.090048 | D12: 1 | E12: 64 | F12: 2 | G12: 256 | H12: 0 | I12: 64 | J12: 530000 | K12: 1.3586 | L12: 590000 | M12: 1.8198
A13: 12 | B13: =D13&"/"&E13&"/"&F13&"/"&G13&"/"&TEXT(H13,"0.00")&"/"&I13 -> 1/64/2/512/0.00/64 | C13: =($P$2*E13+E13*G13+D13*(12*E13^2+13*E13)+E13*$P$2)/1000000 -> 0.106432 | D13: 1 | E13: 64 | F13: 2 | G13: 512 | H13: 0 | I13: 64 | J13: 610000 | K13: 1.3688 | L13: 490000 | M13: 1.8295
A14: 13 | B14: =D14&"/"&E14&"/"&F14&"/"&G14&"/"&TEXT(H14,"0.00")&"/"&I14 -> 2/64/2/128/0.00/64 | C14: =($P$2*E14+E14*G14+D14*(12*E14^2+13*E14)+E14*$P$2)/1000000 -> 0.13184 | D14: 2 | E14: 64 | F14: 2 | G14: 128 | H14: 0 | I14: 64 | J14: 940000 | K14: 1.138 | L14: 800000 | M14: 1.6839
... A30: 29 | B30: =D30&"/"&E30&"/"&F30&"/"&G30&"/"&TEXT(H30,"0.00")&"/"&I30 -> 3/128/4/256/0.00/64 | C30: =($P$2*E30+E30*G30+D30*(12*E30^2+13*E30)+E30*$P$2)/1000000 -> 0.674944 | D30: 3 | E30: 128 | F30: 4 | G30: 256 | H30: 0 | I30: 64 | J30: 450000 | K30: 0.8399 | L30: 20000 | M30: 1.6159

Sheet Step1_with_dropout
A1: № | B1: Модель | C1: model size M | D1: n_layer | E1: n_embd | F1: n_head | G1: block_size | H1: dropout | I1: batch_size | J1: train iterations | K1: train loss | L1: val iterations | M1: val loss
A2: 1 | B2: =D2&"/"&E2&"/"&F2&"/"&G2&"/"&TEXT(H2,"0.00")&"/"&I2 -> 3/128/4/128/0.05/64 | C2: =($P$2*E2+E2*G2+D2*(12*E2^2+13*E2)+E2*$P$2)/1000000 -> 0.65856 | D2: 3 | E2: 128 | F2: 4 | G2: 128 | H2: 0.05 | I2: 64 | J2: 910000 | K2: 0.8969 | L2: 850000 | M2: 1.4479 | O2: vocab_size | P2: 185
A3: 2 | B3: =D3&"/"&E3&"/"&F3&"/"&G3&"/"&TEXT(H3,"0.00")&"/"&I3 -> 3/128/4/256/0.05/64 | C3: =($P$2*E3+E3*G3+D3*(12*E3^2+13*E3)+E3*$P$2)/1000000 -> 0.674944 | D3: 3 | E3: 128 | F3: 4 | G3: 256 | H3: 0.05 | I3: 64 | J3: 630000 | K3: 0.8386 | L3: 350000 | M3: 1.3999
A4: 3 | B4: =D4&"/"&E4&"/"&F4&"/"&G4&"/"&TEXT(H4,"0.00")&"/"&I4 -> 3/128/4/128/0.10/64 | C4: =($P$2*E4+E4*G4+D4*(12*E4^2+13*E4)+E4*$P$2)/1000000 -> 0.65856 | D4: 3 | E4: 128 | F4: 4 | G4: 128 | H4: 0.1 | I4: 64 | J4: 740000 | K4: 0.9397 | L4: 620000 | M4: 1.4592
A5: 4 | B5: =D5&"/"&E5&"/"&F5&"/"&G5&"/"&TEXT(H5,"0.00")&"/"&I5 -> 3/128/4/256/0.10/64 | C5: =($P$2*E5+E5*G5+D5*(12*E5^2+13*E5)+E5*$P$2)/1000000 -> 0.674944 | D5: 3 | E5: 128 | F5: 4 | G5: 256 | H5: 0.1 | I5: 64 | J5: 760000 | K5: 0.8686 | L5: 380000 | M5: 1.408
A6: 5 | B6: =D6&"/"&E6&"/"&F6&"/"&G6&"/"&TEXT(H6,"0.00")&"/"&I6 -> 4/128/4/256/0.05/64 | C6: =($P$2*E6+E6*G6+D6*(12*E6^2+13*E6)+E6*$P$2)/1000000 -> 0.873216 | D6: 4 | E6: 128 | F6: 4 | G6: 256 | H6: 0.05 | I6: 64 | J6: 400000 | K6: 0.8095 | L6: 450000 | M6: 1.4447
A7: 6 | B7: =D7&"/"&E7&"/"&F7&"/"&G7&"/"&TEXT(H7,"0.00")&"/"&I7 -> 4/128/4/512/0.05/64 | C7: =($P$2*E7+E7*G7+D7*(12*E7^2+13*E7)+E7*$P$2)/1000000 -> 0.905984 | D7: 4 | E7: 128 | F7: 4 | G7: 512 | H7: 0.05 | I7: 64 | J7: 270000 | K7: 0.7781 | L7: 180000 | M7: 1.3395
A8: 7 | B8: =D8&"/"&E8&"/"&F8&"/"&G8&"/"&TEXT(H8,"0.00")&"/"&I8 -> 3/192/6/512/0.05/32 | C8: =($P$2*E8+E8*G8+D8*(12*E8^2+13*E8)+E8*$P$2)/1000000 -> 1.503936 | D8: 3 | E8: 192 | F8: 6 | G8: 512 | H8: 0.05 | I8: 32 | J8: 350000 | K8: 0.7043 | L8: 130000 | M8: 1.3392
A9: 8 | B9: =D9&"/"&E9&"/"&F9&"/"&G9&"/"&TEXT(H9,"0.00")&"/"&I9 -> 3/192/6/1024/0.05/32 | C9: =($P$2*E9+E9*G9+D9*(12*E9^2+13*E9)+E9*$P$2)/1000000 -> 1.60224 | D9: 3 | E9: 192 | F9: 6 | G9: 1024 | H9: 0.05 | I9: 32 | J9: 120000 | K9: 0.7457 | L9: 100000 | M9: 1.2775
A10: 9 | B10: =D10&"/"&E10&"/"&F10&"/"&G10&"/"&TEXT(H10,"0.00")&"/"&I10 -> 4/192/6/1024/0.05/8 | C10: =($P$2*E10+E10*G10+D10*(12*E10^2+13*E10)+E10*$P$2)/1000000 -> 2.047104 | D10: 4 | E10: 192 | F10: 6 | G10: 1024 | H10: 0.05 | I10: 8 | J10: 250000 | K10: 0.6898 | L10: 230000 | M10: 1.2453
A11: 10 | B11: =D11&"/"&E11&"/"&F11&"/"&G11&"/"&TEXT(H11,"0.00")&"/"&I11 -> 4/192/6/1536/0.05/8 | C11: =($P$2*E11+E11*G11+D11*(12*E11^2+13*E11)+E11*$P$2)/1000000 -> 2.145408 | D11: 4 | E11: 192 | F11: 6 | G11: 1536 | H11: 0.05 | I11: 8 | J11: 260000 | K11: 0.6677 | L11: 240000 | M11: 1.2115
A12: 11 | B12: =D12&"/"&E12&"/"&F12&"/"&G12&"/"&TEXT(H12,"0.00")&"/"&I12 -> 10/128/4/1536/0.05/8 | C12: =($P$2*E12+E12*G12+D12*(12*E12^2+13*E12)+E12*$P$2)/1000000 -> 2.226688 | D12: 10 | E12: 128 | F12: 4 | G12: 1536 | H12: 0.05 | I12: 8 | J12: 80000 | K12: 0.6757 | L12: 50000 | M12: 1.1731
A13: 12 | B13: =D13&"/"&E13&"/"&F13&"/"&G13&"/"&TEXT(H13,"0.00")&"/"&I13 -> 5/192/6/1536/0.05/8 | C13: =($P$2*E13+E13*G13+D13*(12*E13^2+13*E13)+E13*$P$2)/1000000 -> 2.590272 | D13: 5 | E13: 192 | F13: 6 | G13: 1536 | H13: 0.05 | I13: 8 | J13: 220000 | K13: 0.6193 | L13: 80000 | M13: 1.2045
A14: 13 | B14: =D14&"/"&E14&"/"&F14&"/"&G14&"/"&TEXT(H14,"0.00")&"/"&I14 -> 5/192/6/2048/0.05/8 | C14: =($P$2*E14+E14*G14+D14*(12*E14^2+13*E14)+E14*$P$2)/1000000 -> 2.688576 | D14: 5 | E14: 192 | F14: 6 | G14: 2048 | H14: 0.05 | I14: 8 | J14: 160000 | K14: 0.6268 | L14: 50000 | M14: 1.1879
... A41: 40 | B41: =D41&"/"&E41&"/"&F41&"/"&G41&"/"&TEXT(H41,"0.00")&"/"&I41 -> 8/288/9/2048/0.15/4 | C41: =($P$2*E41+E41*G41+D41*(12*E41^2+13*E41)+E41*$P$2)/1000000 -> 8.68896 | D41: 8 | E41: 288 | F41: 9 | G41: 2048 | H41: 0.15 | I41: 4 | J41: 70000 | K41: 0.5733 | L41: 50000 | M41: 1.0852

Sheet Step1_final
A1: № | B1: iterations | C1: Params | D1: =D3&"/"&D4&"/"&D5&"/"&D6&"/"&TEXT(D7,"0.00")&"/"&D8 -> 12/128/4/2048/0.10/4 | F1: =F3&"/"&F4&"/"&F5&"/"&F6&"/"&TEXT(F7,"0.00")&"/"&F8 -> 10/192/6/2048/0.10/4 | H1: =H3&"/"&H4&"/"&H5&"/"&H6&"/"&TEXT(H7,"0.00")&"/"&H8 -> 8/256/8/2048/0.15/4
A2: 1 | C2: model size, M | D2: =($M$2*D4+D4*D6+D3*(12*D4^2+13*D4)+D4*$M$2)/1000000 -> 2.688768 | F2: =($M$2*F4+F4*F6+F3*(12*F4^2+13*F4)+F4*$M$2)/1000000 -> 4.912896 | H2: =($M$2*H4+H4*H6+H3*(12*H4^2+13*H4)+H4*$M$2)/1000000 -> 6.937088 | L2: vocab_size | M2: 185
A3: 2 | C3: n_layer | D3: 12 | F3: 10 | H3: 8
A4: 3 | C4: n_embd | D4: 128 | F4: 192 | H4: 256
A5: 4 | C5: n_head | D5: 4 | F5: 6 | H5: 8
A6: 5 | C6: block_size | D6: 2048 | F6: 2048 | H6: 2048
A7: 6 | C7: dropout | D7: 0.1 | F7: 0.1 | H7: 0.15
A8: 7 | C8: batch_size | D8: 4 | F8: 4 | H8: 4
A9: 8 | B9: 0 | C9: duration / val/train | D9: 5 | E9: =D11/D10 -> 1.0148408 | F9: 5 | G9: =F11/F10 -> 1.0378408 | H9: 5 | I9: =H11/H10 -> 1.0245572
A10: 9 | C10: train loss | D10: 4.6763 | F10: 4.585 | H10: 4.5445
A11: 10 | C11: val loss | D11: 4.7457 | F11: 4.7585 | H11: 4.6561
A12: 11 | B12: 2000 | C12: duration / val/train | D12: 297 | E12: =D14/D13 -> 1.1154444 | F12: 403 | G12: =F14/F13 -> 1.1176129 | H12: 408 | I12: =H14/H13 -> 1.1226111
A13: 12 | C13: train loss / train diff % | D13: 2.4462 | E13: =(D13-D10)/D10 -> -0.47689413 | F13: 2.4113 | G13: =(F13-F10)/F10 -> -0.47408942 | H13: 2.3913 | I13: =(H13-H10)/H10 -> -0.4738035
A14: 13 | C14: val loss / val diff % | D14: 2.7286 | E14: =(D14-D11)/D11 -> -0.4250374 | F14: 2.6949 | G14: =(F14-F11)/F11 -> -0.43366607 | H14: 2.6845 | I14: =(H14-H11)/H11 -> -0.42344451
A15: 14 | B15: 4000 | C15: duration / val/train | D15: 590 | E15: =D17/D16 -> 1.2040325 | F15: 799 | G15: =F17/F16 -> 1.2712572 | H15: 814 | I15: =H17/H16 -> 1.2720298
A16: 15 | C16: train loss / train diff % | D16: 1.9095 | E16: =(D16-D13)/D13 -> -0.21940152 | F16: 1.5336 | G16: =(F16-F13)/F13 -> -0.36399453 | H16: 1.3686 | I16: =(H16-H13)/H13 -> -0.42767532
A17: 16 | C17: val loss / val diff % | D17: 2.2991 | E17: =(D17-D14)/D14 -> -0.15740673 | F17: 1.9496 | G17: =(F17-F14)/F14 -> -0.27655943 | H17: 1.7409 | I17: =(H17-H14)/H14 -> -0.35149935
A18: 17 | B18: 6000 | C18: duration / val/train | D18: 880 | E18: =D20/D19 -> 1.2991426 | F18: 1192 | G18: =F20/F19 -> 1.3368548 | H18: 1215 | I18: =H20/H19 -> 1.3296046
A19: 18 | C19: train loss / train diff % | D19: 1.2713 | E19: =(D19-D16)/D16 -> -0.33422362 | F19: 1.0791 | G19: =(F19-F16)/F16 -> -0.2963615 | H19: 1.037 | I19: =(H19-H16)/H16 -> -0.24229139
A20: 19 | C20: val loss / val diff % | D20: 1.6516 | E20: =(D20-D17)/D17 -> -0.28163194 | F20: 1.4426 | G20: =(F20-F17)/F17 -> -0.26005334 | H20: 1.3788 | I20: =(H20-H17)/H17 -> -0.20799586
A21: 20 | B21: 8000 | C21: duration / val/train | D21: 1170 | E21: =D23/D22 -> 1.344767 | F21: 1570 | G21: =F23/F22 -> 1.361204 | H21: 1618 | I21: =H23/H22 -> 1.3586574
A22: 21 | C22: train loss / train diff % | D22: 1.0816 | E22: =(D22-D19)/D19 -> -0.14921734 | F22: 0.9568 | G22: =(F22-F19)/F19 -> -0.11333519 | H22: 0.9385 | I22: =(H22-H19)/H19 -> -0.094985535
A23: 22 | C23: val loss / val diff % | D23: 1.4545 | E23: =(D23-D20)/D20 -> -0.11933882 | F23: 1.3024 | G23: =(F23-F20)/F20 -> -0.097185637 | H23: 1.2751 | I23: =(H23-H20)/H20 -> -0.075210328
A24: 23 | B24: 10000 | C24: duration / val/train | D24: 1460 | E24: =D26/D25 -> 1.3392786 | F24: 1938 | G24: =F26/F25 -> 1.3747792 | H24: 2033 | I24: =H26/H25 -> 1.3622083
A25: 24 | C25: train loss / train diff % | D25: 1.0036 | E25: =(D25-D22)/D22 -> -0.072115385 | F25: 0.9056 | G25: =(F25-F22)/F22 -> -0.053511706 | H25: 0.8785 | I25: =(H25-H22)/H22 -> -0.063931806
A26: 25 | C26: val loss / val diff % | D26: 1.3441 | E26: =(D26-D23)/D23 -> -0.075902372 | F26: 1.245 | G26: =(F26-F23)/F23 -> -0.044072482 | H26: 1.1967 | I26: =(H26-H23)/H23 -> -0.061485374
A27: 26 | B27: 12000 | C27: duration / val/train | D27: 1750 | E27: =D29/D28 -> 1.3885478 | F27: 2303 | G27: =F29/F28 -> 1.4015775 | H27: 2436 | I27: =H29/H28 -> 1.4080734
A28: 27 | C28: train loss / train diff % | D28: 0.9448 | E28: =(D28-D25)/D25 -> -0.058589079 | F28: 0.8621 | G28: =(F28-F25)/F25 -> -0.048034452 | H28: 0.8398 | I28: =(H28-H25)/H25 -> -0.044052362
A29: 28 | C29: val loss / val diff % | D29: 1.3119 | E29: =(D29-D26)/D26 -> -0.023956551 | F29: 1.2083 | G29: =(F29-F26)/F26 -> -0.029477912 | H29: 1.1825 | I29: =(H29-H26)/H26 -> -0.011865965
A30: 29 | B30: 14000 | C30: duration / val/train | D30: 2040 | E30: =D32/D31 -> 1.4095808 | F30: 2668 | G30: =F32/F31 -> 1.4629853 | H30: 2845 | I30: =H32/H31 -> 1.4314646
A31: 30 | C31: train loss / train diff % | D31: 0.9185 | E31: =(D31-D28)/D28 -> -0.027836579 | F31: 0.8294 | G31: =(F31-F28)/F28 -> -0.037930634 | H31: 0.8098 | I31: =(H31-H28)/H28 -> -0.035722791
A32: 31 | C32: val loss / val diff % | D32: 1.2947 | E32: =(D32-D29)/D29 -> -0.013110755 | F32: 1.2134 | G32: =(F32-F29)/F29 -> 0.0042208061 | H32: 1.1592 | I32: =(H32-H29)/H29 -> -0.019704017
A33: 32 | B33: 16000 | C33: duration / val/train | D33: 2331 | E33: =D35/D34 -> 1.399095 | F33: 3033 | G33: =F35/F34 -> 1.4391593 | H33: 3261 | I33: =H35/H34 -> 1.4477273
A34: 33 | C34: train loss / train diff % | D34: 0.884 | E34: =(D34-D31)/D31 -> -0.037561241 | F34: 0.8136 | G34: =(F34-F31)/F31 -> -0.019049916 | H34: 0.792 | I34: =(H34-H31)/H31 -> -0.021980736
A35: 34 | C35: val loss / val diff % | D35: 1.2368 | E35: =(D35-D32)/D32 -> -0.044720785 | F35: 1.1709 | G35: =(F35-F32)/F32 -> -0.035025548 | H35: 1.1466 | I35: =(H35-H32)/H32 -> -0.010869565
A36: 35 | B36: 18000 | C36: duration / val/train | D36: 2621 | E36: =D38/D37 -> 1.4195038 | F36: 3397 | G36: =F38/F37 -> 1.4661243 | H36: 3676 | I36: =H38/H37 -> 1.4896552
A37: 36 | C37: train loss / train diff % | D37: 0.8665 | E37: =(D37-D34)/D34 -> -0.01979638 | F37: 0.7867 | G37: =(F37-F34)/F34 -> -0.03306293 | H37: 0.7685 | I37: =(H37-H34)/H34 -> -0.029671717
A38: 37 | C38: val loss / val diff % | D38: 1.23 | E38: =(D38-D35)/D35 -> -0.0054980595 | F38: 1.1534 | G38: =(F38-F35)/F35 -> -0.014945768 | H38: 1.1448 | I38: =(H38-H35)/H35 -> -0.0015698587
A39: 38 | B39: 20000 | C39: duration / val/train | D39: 2911 | E39: =D41/D40 -> 1.4445756 | F39: 3762 | G39: =F41/F40 -> 1.4733359 | H39: 4072 | I39: =H41/H40 -> 1.5006605
A40: 39 | C40: train loss / train diff % | D40: 0.8471 | E40: =(D40-D37)/D37 -> -0.022388921 | F40: 0.7707 | G40: =(F40-F37)/F37 -> -0.020338121 | H40: 0.757 | I40: =(H40-H37)/H37 -> -0.014964216
...

Sheet Step1_checkponts
A1: № | B1: Checkpoints | C1: Params | D1: =D3&"/"&D4&"/"&D5&"/"&D6&"/"&TEXT(D7,"0.00")&"/"&D8 -> 12/128/4/2048/0.10/4 | E1: =E3&"/"&E4&"/"&E5&"/"&E6&"/"&TEXT(E7,"0.00")&"/"&E8 -> 10/192/6/2048/0.10/4 | F1: =F3&"/"&F4&"/"&F5&"/"&F6&"/"&TEXT(F7,"0.00")&"/"&F8 -> 8/256/8/2048/0.15/4
A2: 1 | C2: model size, M | D2: =($J$2*D4+D4*D6+D3*(12*D4^2+13*D4)+D4*$J$2)/1000000 -> 2.688768 | E2: =($J$2*E4+E4*E6+E3*(12*E4^2+13*E4)+E4*$J$2)/1000000 -> 4.912896 | F2: =($J$2*F4+F4*F6+F3*(12*F4^2+13*F4)+F4*$J$2)/1000000 -> 6.937088 | I2: vocab_size | J2: 185
A3: 2 | C3: n_layer | D3: 12 | E3: 10 | F3: 8
A4: 3 | C4: n_embd | D4: 128 | E4: 192 | F4: 256
A5: 4 | C5: n_head | D5: 4 | E5: 6 | F5: 8
A6: 5 | C6: block_size | D6: 2048 | E6: 2048 | F6: 2048
A7: 6 | C7: dropout | D7: 0.1 | E7: 0.1 | F7: 0.15
A8: 7 | C8: batch_size | D8: 4 | E8: 4 | F8: 4
A9: 8 | B9: val loss plateau | C9: iterations | D9: 96000 | E9: 38000 | F9: 32000
A10: 9 | C10: duration | D10: 13934 | E10: 7151 | F10: 6441
A11: 10 | C11: train loss | D11: 0.6692 | E11: 0.6842 | F11: 0.6914
A12: 11 | C12: val loss | D12: 1.106 | E12: 1.0988 | F12: 1.0867
A13: 12 | B13: min val loss | C13: iterations | D13: 232000 | E13: 76000 | F13: 56000
A14: 13 | C14: duration | D14: 34159 | E14: 14321 | F14: 11109
A15: 14 | C15: train loss | D15: 0.6136 | E15: 0.6078 | F15: 0.6195
A16: 15 | C16: val loss | D16: 1.0808 | E16: 1.0877 | F16: 1.0731
A17: 16 | B17: min train loss | C17: iterations | D17: 252000 | E17: 180000 | F17: 196000
A18: 17 | C18: duration | D18: 37172 | E18: 33606 | F18: 39193
A19: 18 | C19: train loss | D19: 0.6035 | E19: 0.5224 | F19: 0.5035
A20: 19 | C20: val loss | D20: 1.1132 | E20: 1.1467 | F20: 1.1503

Sheet Graph1_data
A1: # | B1: iterations | C1: =Step1_final!D1 -> 12/128/4/2048/0.10/4 | F1: =Step1_final!F1 -> 10/192/6/2048/0.10/4 | I1: =Step1_final!H1 -> 8/256/8/2048/0.15/4
C2: Duration | D2: Train loss | E2: Val loss | F2: Duration | G2: Train loss | H2: Val loss | I2: Duration | J2: Train loss | K2: Val loss
A3: 1 | B3: 0 | C3: {=INDEX(Step1_final!D:D, 3 + (ROW(C3)-1)*3)} -> 5 | D3: {=INDEX(Step1_final!D:D, 4 + (ROW(D3)-1)*3)} -> 4.6763 | E3: {=INDEX(Step1_final!D:D, 5 + (ROW(E3)-1)*3)} -> 4.7457 | F3: {=INDEX(Step1_final!F:F, 3 + (ROW(F3)-1)*3)} -> 5 | G3: {=INDEX(Step1_final!F:F, 4 + (ROW(G3)-1)*3)} -> 4.585 | H3: {=INDEX(Step1_final!F:F, 5 + (ROW(H3)-1)*3)} -> 4.7585 | I3: {=INDEX(Step1_final!H:H, 3 + (ROW(I3)-1)*3)} -> 5 | J3: {=INDEX(Step1_final!H:H, 4 + (ROW(J3)-1)*3)} -> 4.5445 | K3: {=INDEX(Step1_final!H:H, 5 + (ROW(K3)-1)*3)} -> 4.6561
A4: 2 | B4: 2000 | C4: {=INDEX(Step1_final!D:D, 3 + (ROW(C4)-1)*3)} -> 297 | D4: {=INDEX(Step1_final!D:D, 4 + (ROW(D4)-1)*3)} -> 2.4462 | E4: {=INDEX(Step1_final!D:D, 5 + (ROW(E4)-1)*3)} -> 2.7286 | F4: {=INDEX(Step1_final!F:F, 3 + (ROW(F4)-1)*3)} -> 403 | G4: {=INDEX(Step1_final!F:F, 4 + (ROW(G4)-1)*3)} -> 2.4113 | H4: {=INDEX(Step1_final!F:F, 5 + (ROW(H4)-1)*3)} -> 2.6949 | I4: {=INDEX(Step1_final!H:H, 3 + (ROW(I4)-1)*3)} -> 408 | J4: {=INDEX(Step1_final!H:H, 4 + (ROW(J4)-1)*3)} -> 2.3913 | K4: {=INDEX(Step1_final!H:H, 5 + (ROW(K4)-1)*3)} -> 2.6845
A5: 3 | B5: 4000 | C5: {=INDEX(Step1_final!D:D, 3 + (ROW(C5)-1)*3)} -> 590 | D5: {=INDEX(Step1_final!D:D, 4 + (ROW(D5)-1)*3)} -> 1.9095 | E5: {=INDEX(Step1_final!D:D, 5 + (ROW(E5)-1)*3)} -> 2.2991 | F5: {=INDEX(Step1_final!F:F, 3 + (ROW(F5)-1)*3)} -> 799 | G5: {=INDEX(Step1_final!F:F, 4 + (ROW(G5)-1)*3)} -> 1.5336 | H5: {=INDEX(Step1_final!F:F, 5 + (ROW(H5)-1)*3)} -> 1.9496 | I5: {=INDEX(Step1_final!H:H, 3 + (ROW(I5)-1)*3)} -> 814 | J5: {=INDEX(Step1_final!H:H, 4 + (ROW(J5)-1)*3)} -> 1.3686 | K5: {=INDEX(Step1_final!H:H, 5 + (ROW(K5)-1)*3)} -> 1.7409
A6: 4 | B6: 6000 | C6: {=INDEX(Step1_final!D:D, 3 + (ROW(C6)-1)*3)} -> 880 | D6: {=INDEX(Step1_final!D:D, 4 + (ROW(D6)-1)*3)} -> 1.2713 | E6: {=INDEX(Step1_final!D:D, 5 + (ROW(E6)-1)*3)} -> 1.6516 | F6: {=INDEX(Step1_final!F:F, 3 + (ROW(F6)-1)*3)} -> 1192 | G6: {=INDEX(Step1_final!F:F, 4 + (ROW(G6)-1)*3)} -> 1.0791 | H6: {=INDEX(Step1_final!F:F, 5 + (ROW(H6)-1)*3)} -> 1.4426 | I6: {=INDEX(Step1_final!H:H, 3 + (ROW(I6)-1)*3)} -> 1215 | J6: {=INDEX(Step1_final!H:H, 4 + (ROW(J6)-1)*3)} -> 1.037 | K6: {=INDEX(Step1_final!H:H, 5 + (ROW(K6)-1)*3)} -> 1.3788
A7: 5 | B7: 8000 | C7: {=INDEX(Step1_final!D:D, 3 + (ROW(C7)-1)*3)} -> 1170 | D7: {=INDEX(Step1_final!D:D, 4 + (ROW(D7)-1)*3)} -> 1.0816 | E7: {=INDEX(Step1_final!D:D, 5 + (ROW(E7)-1)*3)} -> 1.4545 | F7: {=INDEX(Step1_final!F:F, 3 + (ROW(F7)-1)*3)} -> 1570 | G7: {=INDEX(Step1_final!F:F, 4 + (ROW(G7)-1)*3)} -> 0.9568 | H7: {=INDEX(Step1_final!F:F, 5 + (ROW(H7)-1)*3)} -> 1.3024 | I7: {=INDEX(Step1_final!H:H, 3 + (ROW(I7)-1)*3)} -> 1618 | J7: {=INDEX(Step1_final!H:H, 4 + (ROW(J7)-1)*3)} -> 0.9385 | K7: {=INDEX(Step1_final!H:H, 5 + (ROW(K7)-1)*3)} -> 1.2751
A8: 6 | B8: 10000 | C8: {=INDEX(Step1_final!D:D, 3 + (ROW(C8)-1)*3)} -> 1460 | D8: {=INDEX(Step1_final!D:D, 4 + (ROW(D8)-1)*3)} -> 1.0036 | E8: {=INDEX(Step1_final!D:D, 5 + (ROW(E8)-1)*3)} -> 1.3441 | F8: {=INDEX(Step1_final!F:F, 3 + (ROW(F8)-1)*3)} -> 1938 | G8: {=INDEX(Step1_final!F:F, 4 + (ROW(G8)-1)*3)} -> 0.9056 | H8: {=INDEX(Step1_final!F:F, 5 + (ROW(H8)-1)*3)} -> 1.245 | I8: {=INDEX(Step1_final!H:H, 3 + (ROW(I8)-1)*3)} -> 2033 | J8: {=INDEX(Step1_final!H:H, 4 + (ROW(J8)-1)*3)} -> 0.8785 | K8: {=INDEX(Step1_final!H:H, 5 + (ROW(K8)-1)*3)} -> 1.1967
A9: 7 | B9: 12000 | C9: {=INDEX(Step1_final!D:D, 3 + (ROW(C9)-1)*3)} -> 1750 | D9: {=INDEX(Step1_final!D:D, 4 + (ROW(D9)-1)*3)} -> 0.9448 | E9: {=INDEX(Step1_final!D:D, 5 + (ROW(E9)-1)*3)} -> 1.3119 | F9: {=INDEX(Step1_final!F:F, 3 + (ROW(F9)-1)*3)} -> 2303 | G9: {=INDEX(Step1_final!F:F, 4 + (ROW(G9)-1)*3)} -> 0.8621 | H9: {=INDEX(Step1_final!F:F, 5 + (ROW(H9)-1)*3)} -> 1.2083 | I9: {=INDEX(Step1_final!H:H, 3 + (ROW(I9)-1)*3)} -> 2436 | J9: {=INDEX(Step1_final!H:H, 4 + (ROW(J9)-1)*3)} -> 0.8398 | K9: {=INDEX(Step1_final!H:H, 5 + (ROW(K9)-1)*3)} -> 1.1825
A10: 8 | B10: 14000 | C10: {=INDEX(Step1_final!D:D, 3 + (ROW(C10)-1)*3)} -> 2040 | D10: {=INDEX(Step1_final!D:D, 4 + (ROW(D10)-1)*3)} -> 0.9185 | E10: {=INDEX(Step1_final!D:D, 5 + (ROW(E10)-1)*3)} -> 1.2947 | F10: {=INDEX(Step1_final!F:F, 3 + (ROW(F10)-1)*3)} -> 2668 | G10: {=INDEX(Step1_final!F:F, 4 + (ROW(G10)-1)*3)} -> 0.8294 | H10: {=INDEX(Step1_final!F:F, 5 + (ROW(H10)-1)*3)} -> 1.2134 | I10: {=INDEX(Step1_final!H:H, 3 + (ROW(I10)-1)*3)} -> 2845 | J10: {=INDEX(Step1_final!H:H, 4 + (ROW(J10)-1)*3)} -> 0.8098 | K10: {=INDEX(Step1_final!H:H, 5 + (ROW(K10)-1)*3)} -> 1.1592
A11: 9 | B11: 16000 | C11: {=INDEX(Step1_final!D:D, 3 + (ROW(C11)-1)*3)} -> 2331 | D11: {=INDEX(Step1_final!D:D, 4 + (ROW(D11)-1)*3)} -> 0.884 | E11: {=INDEX(Step1_final!D:D, 5 + (ROW(E11)-1)*3)} -> 1.2368 | F11: {=INDEX(Step1_final!F:F, 3 + (ROW(F11)-1)*3)} -> 3033 | G11: {=INDEX(Step1_final!F:F, 4 + (ROW(G11)-1)*3)} -> 0.8136 | H11: {=INDEX(Step1_final!F:F, 5 + (ROW(H11)-1)*3)} -> 1.1709 | I11: {=INDEX(Step1_final!H:H, 3 + (ROW(I11)-1)*3)} -> 3261 | J11: {=INDEX(Step1_final!H:H, 4 + (ROW(J11)-1)*3)} -> 0.792 | K11: {=INDEX(Step1_final!H:H, 5 + (ROW(K11)-1)*3)} -> 1.1466
A12: 10 | B12: 18000 | C12: {=INDEX(Step1_final!D:D, 3 + (ROW(C12)-1)*3)} -> 2621 | D12: {=INDEX(Step1_final!D:D, 4 + (ROW(D12)-1)*3)} -> 0.8665 | E12: {=INDEX(Step1_final!D:D, 5 + (ROW(E12)-1)*3)} -> 1.23 | F12: {=INDEX(Step1_final!F:F, 3 + (ROW(F12)-1)*3)} -> 3397 | G12: {=INDEX(Step1_final!F:F, 4 + (ROW(G12)-1)*3)} -> 0.7867 | H12: {=INDEX(Step1_final!F:F, 5 + (ROW(H12)-1)*3)} -> 1.1534 | I12: {=INDEX(Step1_final!H:H, 3 + (ROW(I12)-1)*3)} -> 3676 | J12: {=INDEX(Step1_final!H:H, 4 + (ROW(J12)-1)*3)} -> 0.7685 | K12: {=INDEX(Step1_final!H:H, 5 + (ROW(K12)-1)*3)} -> 1.1448
A13: 11 | B13: 20000 | C13: {=INDEX(Step1_final!D:D, 3 + (ROW(C13)-1)*3)} -> 2911 | D13: {=INDEX(Step1_final!D:D, 4 + (ROW(D13)-1)*3)} -> 0.8471 | E13: {=INDEX(Step1_final!D:D, 5 + (ROW(E13)-1)*3)} -> 1.2237 | F13: {=INDEX(Step1_final!F:F, 3 + (ROW(F13)-1)*3)} -> 3762 | G13: {=INDEX(Step1_final!F:F, 4 + (ROW(G13)-1)*3)} -> 0.7707 | H13: {=INDEX(Step1_final!F:F, 5 + (ROW(H13)-1)*3)} -> 1.1355 | I13: {=INDEX(Step1_final!H:H, 3 + (ROW(I13)-1)*3)} -> 4072 | J13: {=INDEX(Step1_final!H:H, 4 + (ROW(J13)-1)*3)} -> 0.757 | K13: {=INDEX(Step1_final!H:H, 5 + (ROW(K13)-1)*3)} -> 1.136
A14: 12 | B14: 22000 | C14: {=INDEX(Step1_final!D:D, 3 + (ROW(C14)-1)*3)} -> 3201 | D14: {=INDEX(Step1_final!D:D, 4 + (ROW(D14)-1)*3)} -> 0.8318 | E14: {=INDEX(Step1_final!D:D, 5 + (ROW(E14)-1)*3)} -> 1.1992 | F14: {=INDEX(Step1_final!F:F, 3 + (ROW(F14)-1)*3)} -> 4138 | G14: {=INDEX(Step1_final!F:F, 4 + (ROW(G14)-1)*3)} -> 0.7528 | H14: {=INDEX(Step1_final!F:F, 5 + (ROW(H14)-1)*3)} -> 1.1479 | I14: {=INDEX(Step1_final!H:H, 3 + (ROW(I14)-1)*3)} -> 4483 | J14: {=INDEX(Step1_final!H:H, 4 + (ROW(J14)-1)*3)} -> 0.7413 | K14: {=INDEX(Step1_final!H:H, 5 + (ROW(K14)-1)*3)} -> 1.133
... A113: 111 | B113: 220000 | C113: {=INDEX(Step1_final!D:D, 3 + (ROW(C113)-1)*3)} -> 32415 | D113: {=INDEX(Step1_final!D:D, 4 + (ROW(D113)-1)*3)} -> 0.6127 | E113: {=INDEX(Step1_final!D:D, 5 + (ROW(E113)-1)*3)} -> 1.096 | F113: {=INDEX(Step1_final!F:F, 3 + (ROW(F113)-1)*3)} -> 41145 | G113: {=INDEX(Step1_final!F:F, 4 + (ROW(G113)-1)*3)} -> 0.5122 | H113: {=INDEX(Step1_final!F:F, 5 + (ROW(H113)-1)*3)} -> 1.1666 | I113: {=INDEX(Step1_final!H:H, 3 + (ROW(I113)-1)*3)} -> 44059 | J113: {=INDEX(Step1_final!H:H, 4 + (ROW(J113)-1)*3)} -> 0.5014 | K113: {=INDEX(Step1_final!H:H, 5 + (ROW(K113)-1)*3)} -> 1.1291
A114: 112 | B114: 222000 | C114: {=INDEX(Step1_final!D:D, 3 + (ROW(C114)-1)*3)} -> 32708 | D114: {=INDEX(Step1_final!D:D, 4 + (ROW(D114)-1)*3)} -> 0.6142 | E114: {=INDEX(Step1_final!D:D, 5 + (ROW(E114)-1)*3)} -> 1.0944 | F114: {=INDEX(Step1_final!F:F, 3 + (ROW(F114)-1)*3)} -> 41510 | G114: {=INDEX(Step1_final!F:F, 4 + (ROW(G114)-1)*3)} -> 0.5113 | H114: {=INDEX(Step1_final!F:F, 5 + (ROW(H114)-1)*3)} -> 1.1604
A115: 113 | B115: 224000 | C115: {=INDEX(Step1_final!D:D, 3 + (ROW(C115)-1)*3)} -> 32998 | D115: {=INDEX(Step1_final!D:D, 4 + (ROW(D115)-1)*3)} -> 0.6119 | E115: {=INDEX(Step1_final!D:D, 5 + (ROW(E115)-1)*3)} -> 1.1004 | F115: {=INDEX(Step1_final!F:F, 3 + (ROW(F115)-1)*3)} -> 41874 | G115: {=INDEX(Step1_final!F:F, 4 + (ROW(G115)-1)*3)} -> 0.5128 | H115: {=INDEX(Step1_final!F:F, 5 + (ROW(H115)-1)*3)} -> 1.1785
A116: 114 | B116: 226000 | C116: {=INDEX(Step1_final!D:D, 3 + (ROW(C116)-1)*3)} -> 33289 | D116: {=INDEX(Step1_final!D:D, 4 + (ROW(D116)-1)*3)} -> 0.609 | E116: {=INDEX(Step1_final!D:D, 5 + (ROW(E116)-1)*3)} -> 1.1001 | F116: {=INDEX(Step1_final!F:F, 3 + (ROW(F116)-1)*3)} -> 42239 | G116: {=INDEX(Step1_final!F:F, 4 + (ROW(G116)-1)*3)} -> 0.5149 | H116: {=INDEX(Step1_final!F:F, 5 + (ROW(H116)-1)*3)} -> 1.1605
A117: 115 | B117: 228000 | C117: {=INDEX(Step1_final!D:D, 3 + (ROW(C117)-1)*3)} -> 33579 | D117: {=INDEX(Step1_final!D:D, 4 + (ROW(D117)-1)*3)} -> 0.6151 | E117: {=INDEX(Step1_final!D:D, 5 + (ROW(E117)-1)*3)} -> 1.1023 | F117: {=INDEX(Step1_final!F:F, 3 + (ROW(F117)-1)*3)} -> 42603 | G117: {=INDEX(Step1_final!F:F, 4 + (ROW(G117)-1)*3)} -> 0.5121 | H117: {=INDEX(Step1_final!F:F, 5 + (ROW(H117)-1)*3)} -> 1.1557
A118: 116 | B118: 230000 | C118: {=INDEX(Step1_final!D:D, 3 + (ROW(C118)-1)*3)} -> 33869 | D118: {=INDEX(Step1_final!D:D, 4 + (ROW(D118)-1)*3)} -> 0.6078 | E118: {=INDEX(Step1_final!D:D, 5 + (ROW(E118)-1)*3)} -> 1.1008 | F118: {=INDEX(Step1_final!F:F, 3 + (ROW(F118)-1)*3)} -> 42973 | G118: {=INDEX(Step1_final!F:F, 4 + (ROW(G118)-1)*3)} -> 0.5106 | H118: {=INDEX(Step1_final!F:F, 5 + (ROW(H118)-1)*3)} -> 1.1773
A119: 117 | B119: 232000 | C119: {=INDEX(Step1_final!D:D, 3 + (ROW(C119)-1)*3)} -> 34159 | D119: {=INDEX(Step1_final!D:D, 4 + (ROW(D119)-1)*3)} -> 0.6136 | E119: {=INDEX(Step1_final!D:D, 5 + (ROW(E119)-1)*3)} -> 1.0808
A120: 118 | B120: 234000 | C120: {=INDEX(Step1_final!D:D, 3 + (ROW(C120)-1)*3)} -> 34451 | D120: {=INDEX(Step1_final!D:D, 4 + (ROW(D120)-1)*3)} -> 0.6102 | E120: {=INDEX(Step1_final!D:D, 5 + (ROW(E120)-1)*3)} -> 1.1127
A121: 119 | B121: 236000 | C121: {=INDEX(Step1_final!D:D, 3 + (ROW(C121)-1)*3)} -> 34744 | D121: {=INDEX(Step1_final!D:D, 4 + (ROW(D121)-1)*3)} -> 0.6157 | E121: {=INDEX(Step1_final!D:D, 5 + (ROW(E121)-1)*3)} -> 1.116
A122: 120 | B122: 238000 | C122: {=INDEX(Step1_final!D:D, 3 + (ROW(C122)-1)*3)} -> 35044 | D122: {=INDEX(Step1_final!D:D, 4 + (ROW(D122)-1)*3)} -> 0.6132 | E122: {=INDEX(Step1_final!D:D, 5 + (ROW(E122)-1)*3)} -> 1.0977
A123: 121 | B123: 240000 | C123: {=INDEX(Step1_final!D:D, 3 + (ROW(C123)-1)*3)} -> 35338 | D123: {=INDEX(Step1_final!D:D, 4 + (ROW(D123)-1)*3)} -> 0.6052 | E123: {=INDEX(Step1_final!D:D, 5 + (ROW(E123)-1)*3)} -> 1.0809
A124: 122 | B124: 242000 | C124: {=INDEX(Step1_final!D:D, 3 + (ROW(C124)-1)*3)} -> 35635 | D124: {=INDEX(Step1_final!D:D, 4 + (ROW(D124)-1)*3)} -> 0.6081 | E124: {=INDEX(Step1_final!D:D, 5 + (ROW(E124)-1)*3)} -> 1.0902
A125: 123 | B125: 244000 | C125: {=INDEX(Step1_final!D:D, 3 + (ROW(C125)-1)*3)} -> 35934 | D125: {=INDEX(Step1_final!D:D, 4 + (ROW(D125)-1)*3)} -> 0.6055 | E125: {=INDEX(Step1_final!D:D, 5 + (ROW(E125)-1)*3)} -> 1.0919
A126: 124 | B126: 246000 | C126: {=INDEX(Step1_final!D:D, 3 + (ROW(C126)-1)*3)} -> 36252 | D126: {=INDEX(Step1_final!D:D, 4 + (ROW(D126)-1)*3)} -> 0.6056 | E126: {=INDEX(Step1_final!D:D, 5 + (ROW(E126)-1)*3)} -> 1.1141
A127: 125 | B127: 248000 | C127: {=INDEX(Step1_final!D:D, 3 + (ROW(C127)-1)*3)} -> 36563 | D127: {=INDEX(Step1_final!D:D, 4 + (ROW(D127)-1)*3)} -> 0.6052 | E127: {=INDEX(Step1_final!D:D, 5 + (ROW(E127)-1)*3)} -> 1.0907
A128: 126 | B128: 250000 | C128: {=INDEX(Step1_final!D:D, 3 + (ROW(C128)-1)*3)} -> 36873 | D128: {=INDEX(Step1_final!D:D, 4 + (ROW(D128)-1)*3)} -> 0.607 | E128: {=INDEX(Step1_final!D:D, 5 + (ROW(E128)-1)*3)} -> 1.104
A129: 127 | B129: 252000 | C129: {=INDEX(Step1_final!D:D, 3 + (ROW(C129)-1)*3)} -> 37172 | D129: {=INDEX(Step1_final!D:D, 4 + (ROW(D129)-1)*3)} -> 0.6035 | E129: {=INDEX(Step1_final!D:D, 5 + (ROW(E129)-1)*3)} -> 1.1132
A130: 128 | B130: 254000 | C130: {=INDEX(Step1_final!D:D, 3 + (ROW(C130)-1)*3)} -> 37469 | D130: {=INDEX(Step1_final!D:D, 4 + (ROW(D130)-1)*3)} -> 0.6047 | E130: {=INDEX(Step1_final!D:D, 5 + (ROW(E130)-1)*3)} -> 1.0907
... A146: 144 | B146: 286000 | C146: {=INDEX(Step1_final!D:D, 3 + (ROW(C146)-1)*3)} -> 42320 | D146: {=INDEX(Step1_final!D:D, 4 + (ROW(D146)-1)*3)} -> 0.6013 | E146: {=INDEX(Step1_final!D:D, 5 + (ROW(E146)-1)*3)} -> 1.1058

Sheet Graph1_1

Sheet Graph1_2

Sheet Step2_Models_plan
A1: № | B1: Stage/Params | C1: =C3&"/"&C4&"/"&C5&"/"&C6&"/"&TEXT(C7,"0.00")&"/"&C8 -> 12/128/4/2048/0.10/4 | D1: =D3&"/"&D4&"/"&D5&"/"&D6&"/"&TEXT(D7,"0.00")&"/"&D8 -> 10/192/6/2048/0.10/4 | E1: =E3&"/"&E4&"/"&E5&"/"&E6&"/"&TEXT(E7,"0.00")&"/"&E8 -> 8/256/8/2048/0.15/4
A2: 1 | B2: model size, M | C2: =($I$2*C4+C4*C6+C3*(12*C4^2+13*C4)+C4*$I$2)/1000000 -> 2.688768 | D2: =($I$2*D4+D4*D6+D3*(12*D4^2+13*D4)+D4*$I$2)/1000000 -> 4.912896 | E2: =($I$2*E4+E4*E6+E3*(12*E4^2+13*E4)+E4*$I$2)/1000000 -> 6.937088 | H2: vocab_size | I2: 185
A3: 2 | B3: n_layer | C3: 12 | D3: 10 | E3: 8
A4: 3 | B4: n_embd | C4: 128 | D4: 192 | E4: 256
A5: 4 | B5: n_head | C5: 4 | D5: 6 | E5: 8
A6: 5 | B6: block_size | C6: 2048 | D6: 2048 | E6: 2048
A7: 6 | B7: dropout | C7: 0.1 | D7: 0.1 | E7: 0.15
A8: 7 | B8: batch_size | C8: 4 | D8: 4 | E8: 4
A9: 8 | B9: Start stage 1 | C9: =K9&"/"&L9&"/"&M9&"/"&N9&"/"&TEXT(O9,"0.00")&"/"&P9 -> 2/32/1/128/0.00/64 | D9: =S9&"/"&T9&"/"&U9&"/"&V9&"/"&TEXT(W9,"0.00")&"/"&X9 -> 2/64/2/128/0.00/64 | E9: =AA9&"/"&AB9&"/"&AC9&"/"&AD9&"/"&TEXT(AE9,"0.00")&"/"&AF9 -> 2/64/2/128/0.00/64 | J9: =(Step1_with_dropout!$P$2*L9+L9*N9+K9*(12*L9^2+13*L9)+L9*Step1_with_dropout!$P$2)/1000000 -> 0.041344 | K9: 2 | L9: 32 | M9: 1 | N9: 128 | O9: 0 | P9: 64 | R9: =(Step1_with_dropout!$P$2*T9+T9*V9+S9*(12*T9^2+13*T9)+T9*Step1_with_dropout!$P$2)/1000000 -> 0.13184 | S9: 2 | T9: 64 | U9: 2 | V9: 128 | W9: 0 | X9: 64 | Z9: =(Step1_with_dropout!$P$2*AB9+AB9*AD9+AA9*(12*AB9^2+13*AB9)+AB9*Step1_with_dropout!$P$2)/1000000 -> 0.13184 | AA9: 2 | AB9: 64 | AC9: 2 | AD9: 128 | AE9: 0 | AF9: 64
A10: 9 | B10: Stage 2 | C10: =K10&"/"&L10&"/"&M10&"/"&N10&"/"&TEXT(O10,"0.00")&"/"&P10 -> 4/64/2/256/0.05/64 | D10: =S10&"/"&T10&"/"&U10&"/"&V10&"/"&TEXT(W10,"0.00")&"/"&X10 -> 4/96/3/256/0.05/64 | E10: =AA10&"/"&AB10&"/"&AC10&"/"&AD10&"/"&TEXT(AE10,"0.00")&"/"&AF10 -> 3/96/3/256/0.05/64 | J10: =(Step1_with_dropout!$P$2*L10+L10*N10+K10*(12*L10^2+13*L10)+L10*Step1_with_dropout!$P$2)/1000000 -> 0.24 | K10: 4 | L10: 64 | M10: 2 | N10: 256 | O10: 0.05 | P10: 64 | R10: =(Step1_with_dropout!$P$2*T10+T10*V10+S10*(12*T10^2+13*T10)+T10*Step1_with_dropout!$P$2)/1000000 -> 0.507456 | S10: 4 | T10: 96 | U10: 3 | V10: 256 | W10: 0.05 | X10: 64 | Z10: =(Step1_with_dropout!$P$2*AB10+AB10*AD10+AA10*(12*AB10^2+13*AB10)+AB10*Step1_with_dropout!$P$2)/1000000 -> 0.395616 | AA10: 3 | AB10: 96 | AC10: 3 | AD10: 256 | AE10: 0.05 | AF10: 64
A11: 10 | B11: Stage 3 | C11: =K11&"/"&L11&"/"&M11&"/"&N11&"/"&TEXT(O11,"0.00")&"/"&P11 -> 6/64/2/512/0.05/64 | D11: =S11&"/"&T11&"/"&U11&"/"&V11&"/"&TEXT(W11,"0.00")&"/"&X11 -> 6/128/4/512/0.05/64 | E11: =AA11&"/"&AB11&"/"&AC11&"/"&AD11&"/"&TEXT(AE11,"0.00")&"/"&AF11 -> 4/128/4/512/0.05/64 | J11: =(Step1_with_dropout!$P$2*L11+L11*N11+K11*(12*L11^2+13*L11)+L11*Step1_with_dropout!$P$2)/1000000 -> 0.356352 | K11: 6 | L11: 64 | M11: 2 | N11: 512 | O11: 0.05 | P11: 64 | R11: =(Step1_with_dropout!$P$2*T11+T11*V11+S11*(12*T11^2+13*T11)+T11*Step1_with_dropout!$P$2)/1000000 -> 1.302528 | S11: 6 | T11: 128 | U11: 4 | V11: 512 | W11: 0.05 | X11: 64 | Z11: =(Step1_with_dropout!$P$2*AB11+AB11*AD11+AA11*(12*AB11^2+13*AB11)+AB11*Step1_with_dropout!$P$2)/1000000 -> 0.905984 | AA11: 4 | AB11: 128 | AC11: 4 | AD11: 512 | AE11: 0.05 | AF11: 64
A12: 11 | B12: Stage 4 | C12: =K12&"/"&L12&"/"&M12&"/"&N12&"/"&TEXT(O12,"0.00")&"/"&P12 -> 9/96/3/1024/0.05/32 | D12: =S12&"/"&T12&"/"&U12&"/"&V12&"/"&TEXT(W12,"0.00")&"/"&X12 -> 8/160/5/1536/0.10/8 | E12: =AA12&"/"&AB12&"/"&AC12&"/"&AD12&"/"&TEXT(AE12,"0.00")&"/"&AF12 -> 6/192/6/1536/0.10/8 | J12: =(Step1_with_dropout!$P$2*L12+L12*N12+K12*(12*L12^2+13*L12)+L12*Step1_with_dropout!$P$2)/1000000 -> 1.140384 | K12: 9 | L12: 96 | M12: 3 | N12: 1024 | O12: 0.05 | P12: 32 | R12: =(Step1_with_dropout!$P$2*T12+T12*V12+S12*(12*T12^2+13*T12)+T12*Step1_with_dropout!$P$2)/1000000 -> 2.7792 | S12: 8 | T12: 160 | U12: 5 | V12: 1536 | W12: 0.1 | X12: 8 | Z12: =(Step1_with_dropout!$P$2*AB12+AB12*AD12+AA12*(12*AB12^2+13*AB12)+AB12*Step1_with_dropout!$P$2)/1000000 -> 3.035136 | AA12: 6 | AB12: 192 | AC12: 6 | AD12: 1536 | AE12: 0.1 | AF12: 8
A13: 12 | B13: Final Stage 5 | C13: =K13&"/"&L13&"/"&M13&"/"&N13&"/"&TEXT(O13,"0.00")&"/"&P13 -> 12/128/4/2048/0.10/4 | D13: =S13&"/"&T13&"/"&U13&"/"&V13&"/"&TEXT(W13,"0.00")&"/"&X13 -> 10/192/6/2048/0.10/4 | E13: =AA13&"/"&AB13&"/"&AC13&"/"&AD13&"/"&TEXT(AE13,"0.00")&"/"&AF13 -> 8/256/8/2048/0.15/4 | J13: =(Step1_with_dropout!$P$2*L13+L13*N13+K13*(12*L13^2+13*L13)+L13*Step1_with_dropout!$P$2)/1000000 -> 2.688768 | K13: 12 | L13: 128 | M13: 4 | N13: 2048 | O13: 0.1 | P13: 4 | R13: =(Step1_with_dropout!$P$2*T13+T13*V13+S13*(12*T13^2+13*T13)+T13*Step1_with_dropout!$P$2)/1000000 -> 4.912896 | S13: 10 | T13: 192 | U13: 6 | V13: 2048 | W13: 0.1 | X13: 4 | Z13: =(Step1_with_dropout!$P$2*AB13+AB13*AD13+AA13*(12*AB13^2+13*AB13)+AB13*Step1_with_dropout!$P$2)/1000000 -> 6.937088 | AA13: 8 | AB13: 256 | AC13: 8 | AD13: 2048 | AE13: 0.15 | AF13: 4

Sheet Step2
A1: № | B1: iterations | C1: Params | D1: =D3&"/"&D4&"/"&D5&"/"&D6&"/"&TEXT(D7,"0.00")&"/"&D8 -> 12/128/4/2048/0.10/4 | F1: =F3&"/"&F4&"/"&F5&"/"&F6&"/"&TEXT(F7,"0.00")&"/"&F8 -> 10/192/6/2048/0.10/4 | H1: =H3&"/"&H4&"/"&H5&"/"&H6&"/"&TEXT(H7,"0.00")&"/"&H8 -> 8/256/8/2048/0.15/4 | J1: =J3&"/"&J4&"/"&J5&"/"&J6&"/"&TEXT(J7,"0.00")&"/"&J8 -> 12/128/4/2048/0.10/4 | L1: =L3&"/"&L4&"/"&L5&"/"&L6&"/"&TEXT(L7,"0.00")&"/"&L8 -> 10/192/6/2048/0.10/4 | N1: =N3&"/"&N4&"/"&N5&"/"&N6&"/"&TEXT(N7,"0.00")&"/"&N8 -> 8/256/8/2048/0.15/4
A2: 1 | C2: model size, M | D2: =($R$2*D4+D4*D6+D3*(12*D4^2+13*D4)+D4*$R$2)/1000000 -> 2.688768 | F2: =($R$2*F4+F4*F6+F3*(12*F4^2+13*F4)+F4*$R$2)/1000000 -> 4.912896 | H2: =($R$2*H4+H4*H6+H3*(12*H4^2+13*H4)+H4*$R$2)/1000000 -> 6.937088 | J2: =($R$2*J4+J4*J6+J3*(12*J4^2+13*J4)+J4*$R$2)/1000000 -> 2.688768 | L2: =($R$2*L4+L4*L6+L3*(12*L4^2+13*L4)+L4*$R$2)/1000000 -> 4.912896 | N2: =($R$2*N4+N4*N6+N3*(12*N4^2+13*N4)+N4*$R$2)/1000000 -> 6.937088 | Q2: vocab_size | R2: 185
A3: 2 | C3: n_layer | D3: 12 | F3: 10 | H3: 8 | J3: 12 | L3: 10 | N3: 8
A4: 3 | C4: n_embd | D4: 128 | F4: 192 | H4: 256 | J4: 128 | L4: 192 | N4: 256
A5: 4 | C5: n_head | D5: 4 | F5: 6 | H5: 8 | J5: 4 | L5: 6 | N5: 8
A6: 5 | C6: block_size | D6: 2048 | F6: 2048 | H6: 2048 | J6: 2048 | L6: 2048 | N6: 2048
A7: 6 | C7: dropout | D7: 0.1 | F7: 0.1 | H7: 0.15 | J7: 0.1 | L7: 0.1 | N7: 0.15
A8: 7 | C8: batch_size | D8: 4 | F8: 4 | H8: 4 | J8: 4 | L8: 4 | N8: 4
A9: 8 | C9: zero_new_weights | D9: True | F9: True | H9: True | J9: False | L9: False | N9: False
A10: 9 | B10: Stage 1 | C10: model | D10: =Step2_Models_plan!C9&"/"&D11/1000&"k" -> 2/32/1/128/0.00/64/50k | F10: =Step2_Models_plan!D9&"/"&F11/1000&"k" -> 2/64/2/128/0.00/64/80k | H10: =Step2_Models_plan!E9&"/"&H11/1000&"k" -> 2/64/2/128/0.00/64/80k | J10: =Step2_Models_plan!C9&"/"&J11/1000&"k" -> 2/32/1/128/0.00/64/50k | L10: =Step2_Models_plan!D9&"/"&L11/1000&"k" -> 2/64/2/128/0.00/64/80k | N10: =Step2_Models_plan!E9&"/"&N11/1000&"k" -> 2/64/2/128/0.00/64/80k
A11: 10 | C11: iterations | D11: 50000 | F11: 80000 | H11: 80000 | J11: 50000 | L11: 80000 | N11: 80000
A12: 11 | C12: duration / val/train | D12: 278 | E12: =D14/D13 -> 1.2229145 | F12: 435 | G12: =F14/F13 -> 1.3522363 | H12: 430 | I12: =H14/H13 -> 1.3522363 | J12: 277 | K12: =J14/J13 -> 1.2229145 | L12: 407 | M12: =L14/L13 -> 1.3522363 | N12: 443 | O12: =N14/N13 -> 1.3522363
A13: 12 | C13: train loss | D13: 1.6531 | F13: 1.3102 | H13: 1.3102 | J13: 1.6531 | L13: 1.3102 | N13: 1.3102
A14: 13 | C14: val loss | D14: 2.0216 | F14: 1.7717 | H14: 1.7717 | J14: 2.0216 | L14: 1.7717 | N14: 1.7717
A15: 14 | B15: Stage 2 | C15: model | D15: =Step2_Models_plan!C10&"/"&D16/1000&"k" -> 4/64/2/256/0.05/64/50k | F15: =Step2_Models_plan!D10&"/"&F16/1000&"k" -> 4/96/3/256/0.05/64/75k | H15: =Step2_Models_plan!E10&"/"&H16/1000&"k" -> 3/96/3/256/0.05/64/125k | J15: =Step2_Models_plan!C10&"/"&J16/1000&"k" -> 4/64/2/256/0.05/64/30k | L15: =Step2_Models_plan!D10&"/"&L16/1000&"k" -> 4/96/3/256/0.05/64/85k | N15: =Step2_Models_plan!E10&"/"&N16/1000&"k" -> 3/96/3/256/0.05/64/80k
A16: 15 | C16: iterations | D16: 50000 | F16: 75000 | H16: 125000 | J16: 30000 | L16: 85000 | N16: 80000
A17: 16 | C17: duration / val/train | D17: 454 | E17: =D19/D18 -> 1.357249 | F17: 1102 | G17: =F19/F18 -> 1.4636429 | H17: 1434 | I17: =H19/H18 -> 1.4316086 | J17: 287 | K17: =J19/J18 -> 1.3710049 | L17: 1249 | M17: =L19/L18 -> 1.5175457 | N17: 921 | O17: =N19/N18 -> 1.4330326
A18: 17 | C18: train loss | D18: 1.2112 | E18: =(D18-D13)/D13 -> -0.26731595 | F18: 0.9723 | G18: =(F18-F13)/F13 -> -0.25789956 | H18: 1.0301 | I18: =(H18-H13)/H13 -> -0.21378416 | J18: 1.214 | K18: =(J18-J13)/J13 -> -0.26562216 | L18: 0.9518 | M18: =(L18-L13)/L13 -> -0.27354602 | N18: 1.0087 | O18: =(N18-N13)/N13 -> -0.23011754
A19: 18 | C19: val loss | D19: 1.6439 | E19: =(D19-D14)/D14 -> -0.18683221 | F19: 1.4231 | G19: =(F19-F14)/F14 -> -0.19676017 | H19: 1.4747 | I19: =(H19-H14)/H14 -> -0.1676356 | J19: 1.6644 | K19: =(J19-J14)/J14 -> -0.17669173 | L19: 1.4444 | M19: =(L19-L14)/L14 -> -0.18473782 | N19: 1.4455 | O19: =(N19-N14)/N14 -> -0.18411695
A20: 19 | B20: Stage 3 | C20: model | D20: =Step2_Models_plan!C11&"/"&D21/1000&"k" -> 6/64/2/512/0.05/64/30k | F20: =Step2_Models_plan!D11&"/"&F21/1000&"k" -> 6/128/4/512/0.05/64/20k | H20: =Step2_Models_plan!E11&"/"&H21/1000&"k" -> 4/128/4/512/0.05/64/25k | J20: =Step2_Models_plan!C11&"/"&J21/1000&"k" -> 6/64/2/512/0.05/64/40k | L20: =Step2_Models_plan!D11&"/"&L21/1000&"k" -> 6/128/4/512/0.05/64/25k | N20: =Step2_Models_plan!E11&"/"&N21/1000&"k" -> 4/128/4/512/0.05/64/45k
A21: 20 | C21: iterations | D21: 30000 | F21: 20000 | H21: 25000 | J21: 40000 | L21: 25000 | N21: 45000
A22: 21 | C22: duration / val/train | D22: 1325 | E22: =D24/D23 -> 1.3827052 | F22: 1755 | G22: =F24/F23 -> 1.5963744 | H22: 1547 | I22: =H24/H23 -> 1.4851983 | J22: 1841 | K22: =J24/J23 -> 1.4108966 | L22: 2198 | M22: =L24/L23 -> 1.7175333 | N22: 2664 | O22: =N24/N23 -> 1.6439432
A23: 22 | C23: train loss | D23: 1.0269 | E23: =(D23-D18)/D18 -> -0.15216314 | F23: 0.8109 | G23: =(F23-F18)/F18 -> -0.16599815 | H23: 0.8749 | I23: =(H23-H18)/H18 -> -0.15066498 | J23: 0.9893 | K23: =(J23-J18)/J18 -> -0.18509061 | L23: 0.7654 | M23: =(L23-L18)/L18 -> -0.19583946 | N23: 0.8024 | O23: =(N23-N18)/N18 -> -0.20452067
A24: 23 | C24: val loss | D24: 1.4199 | E24: =(D24-D19)/D19 -> -0.13626133 | F24: 1.2945 | G24: =(F24-F19)/F19 -> -0.090366102 | H24: 1.2994 | I24: =(H24-H19)/H19 -> -0.11887163 | J24: 1.3958 | K24: =(J24-J19)/J19 -> -0.16137948 | L24: 1.3146 | M24: =(L24-L19)/L19 -> -0.089864304 | N24: 1.3191 | O24: =(N24-N19)/N19 -> -0.087443791
A25: 24 | B25: Stage 4 | C25: model | D25: =Step2_Models_plan!C12&"/"&D26/1000&"k" -> 9/96/3/1024/0.05/32/35k | F25: =Step2_Models_plan!D12&"/"&F26/1000&"k" -> 8/160/5/1536/0.10/8/50k | H25: =Step2_Models_plan!E12&"/"&H26/1000&"k" -> 6/192/6/1536/0.10/8/60k | J25: =Step2_Models_plan!C12&"/"&J26/1000&"k" -> 9/96/3/1024/0.05/32/35k | L25: =Step2_Models_plan!D12&"/"&L26/1000&"k" -> 8/160/5/1536/0.10/8/45k | N25: =Step2_Models_plan!E12&"/"&N26/1000&"k" -> 6/192/6/1536/0.10/8/40k
A26: 25 | C26: iterations | D26: 35000 | F26: 50000 | H26: 60000 | J26: 35000 | L26: 45000 | N26: 40000
A27: 26 | C27: duration / val/train | D27: 6102 | E27: =D29/D28 -> 1.5204322 | F27: 7230 | G27: =F29/F28 -> 1.6178885 | H27: 8004 | I27: =H29/H28 -> 1.6069232 | J27: 6290 | K27: =J29/J28 -> 1.5974475 | L27: 6630 | M27: =L29/L28 -> 1.7247259 | N27: 5217 | O27: =N29/N28 -> 1.7248557
A28: 27 | C28: train loss | D28: 0.8051 | E28: =(D28-D23)/D23 -> -0.21598987 | F28: 0.6943 | G28: =(F28-F23)/F23 -> -0.14379085 | H28: 0.6991 | I28: =(H28-H23)/H23 -> -0.20093725 | J28: 0.7522 | K28: =(J28-J23)/J23 -> -0.23966441 | L28: 0.6568 | M28: =(L28-L23)/L23 -> -0.1418866 | N28: 0.6582 | O28: =(N28-N23)/N23 -> -0.17971087
A29: 28 | C29: val loss | D29: 1.2241 | E29: =(D29-D24)/D24 -> -0.13789704 | F29: 1.1233 | G29: =(F29-F24)/F24 -> -0.13225183 | H29: 1.1234 | I29: =(H29-H24)/H24 -> -0.13544713 | J29: 1.2016 | K29: =(J29-J24)/J24 -> -0.13913168 | L29: 1.1328 | M29: =(L29-L24)/L24 -> -0.13829302 | N29: 1.1353 | O29: =(N29-N24)/N24 -> -0.13933743
A30: 29 | C30: Total time | D30: =D12+D17+D22+D27 -> 8159 | F30: =F12+F17+F22+F27 -> 10522 | H30: =H12+H17+H22+H27 -> 11415 | J30: =J12+J17+J22+J27 -> 8695 | L30: =L12+L17+L22+L27 -> 10484 | N30: =N12+N17+N22+N27 -> 9245
A31: 30 | B31: 0 | C31: duration / val/train | D31: 0 | E31: =D33/D32 -> 1.1005598 | F31: 0 | G31: =F33/F32 -> 0.92445596 | H31: 0 | I31: =H33/H32 -> 1.1016521 | J31: 0 | K31: =J33/J32 -> 1.0782736 | L31: 0 | M31: =L33/L32 -> 1.0045748 | N31: 0 | O31: =N33/N32 -> 1.0871761
A32: 31 | C32: train loss | D32: 3.8584 | F32: 3.7819 | H32: 3.5651 | J32: 3.9528 | L32: 3.7379 | N32: 3.1878
A33: 32 | C33: val loss | D33: 4.2464 | F33: 3.4962 | H33: 3.9275 | J33: 4.2622 | L33: 3.755 | N33: 3.4657
A34: 33 | B34: 2000 | C34: duration / val/train | D34: 290 | E34: =D36/D35 -> 1.2689051 | F34: 364 | G34: =F36/F35 -> 1.4598882 | H34: 409 | I34: =H36/H35 -> 1.374717 | J34: 291 | K34: =J36/J35 -> 1.3145997 | L34: 370 | M34: =L36/L35 -> 1.5117686 | N34: 390 | O34: =N36/N35 -> 1.4308622
A35: 34 | C35: train loss / train diff % | D35: 1.0156 | E35: =(D35-D32)/D32 -> -0.73678209 | F35: 0.7691 | G35: =(F35-F32)/F32 -> -0.79663661 | H35: 0.8393 | I35: =(H35-H32)/H32 -> -0.76457883 | J35: 0.9555 | K35: =(J35-J32)/J32 -> -0.75827262 | L35: 0.7605 | M35: =(L35-L32)/L32 -> -0.79654351 | N35: 0.8107 | O35: =(N35-N32)/N32 -> -0.74568668
A36: 35 | C36: val loss / val diff % | D36: 1.2887 | E36: =(D36-D33)/D33 -> -0.6965194 | F36: 1.1228 | G36: =(F36-F33)/F33 -> -0.67885132 | H36: 1.1538 | I36: =(H36-H33)/H33 -> -0.70622533 | J36: 1.2561 | K36: =(J36-J33)/J33 -> -0.70529304 | L36: 1.1497 | M36: =(L36-L33)/L33 -> -0.69382157 | N36: 1.16 | O36: =(N36-N33)/N33 -> -0.66529128
A37: 36 | B37: 4000 | C37: duration / val/train | D37: 580 | E37: =D39/D38 -> 1.31014 | F37: 728 | G37: =F39/F38 -> 1.4812329 | H37: 819 | I37: =H39/H38 -> 1.4192371 | J37: 581 | K37: =J39/J38 -> 1.3607857 | L37: 742 | M37: =L39/L38 -> 1.5399547 | N37: 779 | O37: =N39/N38 -> 1.5283884
A38: 37 | C38: train loss / train diff % | D38: 0.9428 | E38: =(D38-D35)/D35 -> -0.071681764 | F38: 0.73 | G38: =(F38-F35)/F35 -> -0.050838643 | H38: 0.7943 | I38: =(H38-H35)/H35 -> -0.053616109 | J38: 0.8706 | K38: =(J38-J35)/J35 -> -0.088854003 | L38: 0.7058 | M38: =(L38-L35)/L35 -> -0.071926364 | N38: 0.7415 | O38: =(N38-N35)/N35 -> -0.085358332
A39: 38 | C39: val loss / val diff % | D39: 1.2352 | E39: =(D39-D36)/D36 -> -0.041514705 | F39: 1.0813 | G39: =(F39-F36)/F36 -> -0.036961169 | H39: 1.1273 | I39: =(H39-H36)/H36 -> -0.022967585 | J39: 1.1847 | K39: =(J39-J36)/J36 -> -0.056842608 | L39: 1.0869 | M39: =(L39-L36)/L36 -> -0.054622945 | N39: 1.1333 | O39: =(N39-N36)/N36 -> -0.023017241
A40: 39 | B40: 6000 | C40: duration / val/train | D40: 869 | E40: =D42/D41 -> 1.3180281 | F40: 1092 | G40: =F42/F41 -> 1.5517193 | H40: 1234 | I40: =H42/H41 -> 1.4590715 | J40: 871 | K40: =J42/J41 -> 1.3777017 | L40: 1110 | M40: =L42/L41 -> 1.5893798 | N40: 1168 | O40: =N42/N41 -> 1.5696676
...

Sheet Step2_checkponts
A1: № | B1: Checkpoints | D1: Params | E1: =E3&"/"&E4&"/"&E5&"/"&E6&"/"&TEXT(E7,"0.00")&"/"&E8 -> 12/128/4/2048/0.10/4 | F1: =F3&"/"&F4&"/"&F5&"/"&F6&"/"&TEXT(F7,"0.00")&"/"&F8 -> 10/192/6/2048/0.10/4 | G1: =G3&"/"&G4&"/"&G5&"/"&G6&"/"&TEXT(G7,"0.00")&"/"&G8 -> 8/256/8/2048/0.15/4
A2: 1 | D2: model size, M | E2: =($K$2*E4+E4*E6+E3*(12*E4^2+13*E4)+E4*$K$2)/1000000 -> 2.688768 | F2: =($K$2*F4+F4*F6+F3*(12*F4^2+13*F4)+F4*$K$2)/1000000 -> 4.912896 | G2: =($K$2*G4+G4*G6+G3*(12*G4^2+13*G4)+G4*$K$2)/1000000 -> 6.937088 | J2: vocab_size | K2: 185
A3: 2 | D3: n_layer | E3: 12 | F3: 10 | G3: 8
A4: 3 | D4: n_embd | E4: 128 | F4: 192 | G4: 256
A5: 4 | D5: n_head | E5: 4 | F5: 6 | G5: 8
A6: 5 | D6: block_size | E6: 2048 | F6: 2048 | G6: 2048
A7: 6 | D7: dropout | E7: 0.1 | F7: 0.1 | G7: 0.15
A8: 7 | D8: batch_size | E8: 4 | F8: 4 | G8: 4
A9: 8 | B9: val loss plateau | C9: Step 1 | D9: iterations | E9: 96000 | F9: 38000 | G9: 32000
A10: 9 | D10: duration | E10: 13934 | F10: 7151 | G10: 6441
A11: 10 | D11: train loss | E11: 0.6692 | F11: 0.6842 | G11: 0.6914
A12: 11 | D12: val loss | E12: 1.106 | F12: 1.0988 | G12: 1.0867
A13: 12 | C13: Step 2 zero | D13: iterations | E13: 38000 | F13: 10000 | G13: 14000
A14: 13 | D14: duration | E14: =5505+Step2!$D$30 -> 13664 | F14: =1820+Step2!$F$30 -> 12342 | G14: =2837+Step2!$H$30 -> 14252
A15: 14 | D15: train loss | E15: 0.7626 | F15: 0.6965 | G15: 0.7124
A16: 15 | D16: val loss | E16: 1.1131 | F16: 1.094 | G16: 1.0907
A17: 16 | D17: duration diff % | E17: =E14/E$10 -> 0.98062294 | F17: =F14/F$10 -> 1.7259125 | G17: =G14/G$10 -> 2.2126999
A18: 17 | C18: Step 2 normal | D18: iterations | E18: 22000 | F18: 4000 | G18: 12000
A19: 18 | D19: duration | E19: =3279+Step2!$J$30 -> 11974 | F19: =742+Step2!$L$30 -> 11226 | G19: =2378+Step2!$N$30 -> 11623
A20: 19 | D20: train loss | E20: 0.7393 | F20: 0.7058 | G20: 0.686
A21: 20 | D21: val loss | E21: 1.1101 | F21: 1.0869 | G21: 1.106
A22: 21 | D22: duration diff % | E22: =E19/E$10 -> 0.85933687 | F22: =F19/F$10 -> 1.5698504 | G22: =G19/G$10 -> 1.8045335
A23: 22 | B23: min val loss | C23: Step 1 | D23: iterations | E23: 232000 | F23: 76000 | G23: 56000
A24: 23 | D24: duration | E24: 34159 | F24: 14321 | G24: 11109
A25: 24 | D25: train loss | E25: 0.6136 | F25: 0.6078 | G25: 0.6195
A26: 25 | D26: val loss | E26: 1.0808 | F26: 1.0877 | G26: 1.0731
A27: 26 | C27: Step 2 zero | D27: iterations | E27: 220000 | F27: 4000 | G27: 30000
A28: 27 | D28: duration | E28: =32470+Step2!$D$30 -> 40629 | F28: =728+Step2!$F$30 -> 11250 | G28: =5950+Step2!$H$30 -> 17365
A29: 28 | D29: train loss | E29: 0.6302 | F29: 0.73 | G29: 0.6506
A30: 29 | D30: val loss | E30: 1.0527 | F30: 1.0813 | G30: 1.0658
A31: 30 | D31: val loss diff % | E31: =E30/E$26 -> 0.97400074 | F31: =F30/F$26 -> 0.99411602 | G31: =G30/G$26 -> 0.99319728
A32: 31 | C32: Step 2 normal | D32: iterations | E32: =94000 -> 94000 | F32: 14000 | G32: 30000
A33: 32 | D33: duration | E33: =14011+Step2!$J$30 -> 22706 | F33: =2579+Step2!$L$30 -> 13063 | G33: =6034+Step2!$N$30 -> 15279
A34: 33 | D34: train loss | E34: 0.6133 | F34: 0.6372 | G34: 0.587
A35: 34 | D35: val loss | E35: 1.0902 | F35: 1.0671 | G35: 1.0862
A36: 35 | D36: val loss diff % | E36: =E35/E$26 -> 1.0086973 | F36: =F35/F$26 -> 0.98106095 | G36: =G35/G$26 -> 1.0122076
A37: 36 | B37: min train loss | C37: Step 1 | D37: iterations | E37: 252000 | F37: 180000 | G37: 196000
A38: 37 | D38: duration | E38: 37172 | F38: 33606 | G38: 39193
A39: 38 | D39: train loss | E39: 0.6035 | F39: 0.5224 | G39: 0.5035
A40: 39 | D40: val loss | E40: 1.1132 | F40: 1.1467 | G40: 1.1503
...

Sheet Step3_Models_plan
A1: № | B1: Stage/Params | C1: =C3&"/"&C4&"/"&C5&"/"&C6&"/"&TEXT(C7,"0.00")&"/"&C8 -> 12/128/4/2048/0.10/4 | D1: =D3&"/"&D4&"/"&D5&"/"&D6&"/"&TEXT(D7,"0.00")&"/"&D8 -> 10/192/6/2048/0.10/4 | E1: =E3&"/"&E4&"/"&E5&"/"&E6&"/"&TEXT(E7,"0.00")&"/"&E8 -> 8/256/8/2048/0.15/4
A2: 1 | B2: model size, M | C2: =($I$2*C4+C4*C6+C3*(12*C4^2+13*C4)+C4*$I$2)/1000000 -> 2.688768 | D2: =($I$2*D4+D4*D6+D3*(12*D4^2+13*D4)+D4*$I$2)/1000000 -> 4.912896 | E2: =($I$2*E4+E4*E6+E3*(12*E4^2+13*E4)+E4*$I$2)/1000000 -> 6.937088 | H2: vocab_size | I2: 185
A3: 2 | B3: n_layer | C3: 12 | D3: 10 | E3: 8
A4: 3 | B4: n_embd | C4: 128 | D4: 192 | E4: 256
A5: 4 | B5: n_head | C5: 4 | D5: 6 | E5: 8
A6: 5 | B6: block_size | C6: 2048 | D6: 2048 | E6: 2048
A7: 6 | B7: dropout | C7: 0.1 | D7: 0.1 | E7: 0.15
A8: 7 | B8: batch_size | C8: 4 | D8: 4 | E8: 4
A9: 8 | B9: Start stage 1 | C9: =K9&"/"&L9&"/"&M9&"/"&N9&"/"&TEXT(O9,"0.00")&"/"&P9 -> 2/32/1/128/0.00/64 | D9: =S9&"/"&T9&"/"&U9&"/"&V9&"/"&TEXT(W9,"0.00")&"/"&X9 -> 2/64/2/128/0.00/64 | E9: =AA9&"/"&AB9&"/"&AC9&"/"&AD9&"/"&TEXT(AE9,"0.00")&"/"&AF9 -> 2/64/2/128/0.00/64 | J9: =(Step1_with_dropout!$P$2*L9+L9*N9+K9*(12*L9^2+13*L9)+L9*Step1_with_dropout!$P$2)/1000000 -> 0.041344 | K9: 2 | L9: 32 | M9: 1 | N9: 128 | O9: 0 | P9: 64 | R9: =(Step1_with_dropout!$P$2*T9+T9*V9+S9*(12*T9^2+13*T9)+T9*Step1_with_dropout!$P$2)/1000000 -> 0.13184 | S9: 2 | T9: 64 | U9: 2 | V9: 128 | W9: 0 | X9: 64 | Z9: =(Step1_with_dropout!$P$2*AB9+AB9*AD9+AA9*(12*AB9^2+13*AB9)+AB9*Step1_with_dropout!$P$2)/1000000 -> 0.13184 | AA9: 2 | AB9: 64 | AC9: 2 | AD9: 128 | AE9: 0 | AF9: 64
A10: 9 | B10: Stage 2 | C10: =K10&"/"&L10&"/"&M10&"/"&N10&"/"&TEXT(O10,"0.00")&"/"&P10 -> 4/64/2/256/0.05/64 | D10: =S10&"/"&T10&"/"&U10&"/"&V10&"/"&TEXT(W10,"0.00")&"/"&X10 -> 4/96/3/256/0.05/64 | E10: =AA10&"/"&AB10&"/"&AC10&"/"&AD10&"/"&TEXT(AE10,"0.00")&"/"&AF10 -> 3/96/3/256/0.05/64 | J10: =(Step1_with_dropout!$P$2*L10+L10*N10+K10*(12*L10^2+13*L10)+L10*Step1_with_dropout!$P$2)/1000000 -> 0.24 | K10: 4 | L10: 64 | M10: 2 | N10: 256 | O10: 0.05 | P10: 64 | R10: =(Step1_with_dropout!$P$2*T10+T10*V10+S10*(12*T10^2+13*T10)+T10*Step1_with_dropout!$P$2)/1000000 -> 0.507456 | S10: 4 | T10: 96 | U10: 3 | V10: 256 | W10: 0.05 | X10: 64 | Z10: =(Step1_with_dropout!$P$2*AB10+AB10*AD10+AA10*(12*AB10^2+13*AB10)+AB10*Step1_with_dropout!$P$2)/1000000 -> 0.395616 | AA10: 3 | AB10: 96 | AC10: 3 | AD10: 256 | AE10: 0.05 | AF10: 64
A11: 10 | B11: Stage 3 | C11: =K11&"/"&L11&"/"&M11&"/"&N11&"/"&TEXT(O11,"0.00")&"/"&P11 -> 6/64/2/512/0.05/64 | D11: =S11&"/"&T11&"/"&U11&"/"&V11&"/"&TEXT(W11,"0.00")&"/"&X11 -> 6/128/4/512/0.10/64 | E11: =AA11&"/"&AB11&"/"&AC11&"/"&AD11&"/"&TEXT(AE11,"0.00")&"/"&AF11 -> 4/128/4/512/0.05/64 | J11: =(Step1_with_dropout!$P$2*L11+L11*N11+K11*(12*L11^2+13*L11)+L11*Step1_with_dropout!$P$2)/1000000 -> 0.356352 | K11: 6 | L11: 64 | M11: 2 | N11: 512 | O11: 0.05 | P11: 64 | R11: =(Step1_with_dropout!$P$2*T11+T11*V11+S11*(12*T11^2+13*T11)+T11*Step1_with_dropout!$P$2)/1000000 -> 1.302528 | S11: 6 | T11: 128 | U11: 4 | V11: 512 | W11: 0.1 | X11: 64 | Z11: =(Step1_with_dropout!$P$2*AB11+AB11*AD11+AA11*(12*AB11^2+13*AB11)+AB11*Step1_with_dropout!$P$2)/1000000 -> 0.905984 | AA11: 4 | AB11: 128 | AC11: 4 | AD11: 512 | AE11: 0.05 | AF11: 64
A12: 11 | B12: Stage 4 | C12: =K12&"/"&L12&"/"&M12&"/"&N12&"/"&TEXT(O12,"0.00")&"/"&P12 -> 9/96/3/1024/0.05/32 | D12: =S12&"/"&T12&"/"&U12&"/"&V12&"/"&TEXT(W12,"0.00")&"/"&X12 -> 8/160/5/1536/0.10/8 | E12: =AA12&"/"&AB12&"/"&AC12&"/"&AD12&"/"&TEXT(AE12,"0.00")&"/"&AF12 -> 6/192/6/1536/0.10/8 | J12: =(Step1_with_dropout!$P$2*L12+L12*N12+K12*(12*L12^2+13*L12)+L12*Step1_with_dropout!$P$2)/1000000 -> 1.140384 | K12: 9 | L12: 96 | M12: 3 | N12: 1024 | O12: 0.05 | P12: 32 | R12: =(Step1_with_dropout!$P$2*T12+T12*V12+S12*(12*T12^2+13*T12)+T12*Step1_with_dropout!$P$2)/1000000 -> 2.7792 | S12: 8 | T12: 160 | U12: 5 | V12: 1536 | W12: 0.1 | X12: 8 | Z12: =(Step1_with_dropout!$P$2*AB12+AB12*AD12+AA12*(12*AB12^2+13*AB12)+AB12*Step1_with_dropout!$P$2)/1000000 -> 3.035136 | AA12: 6 | AB12: 192 | AC12: 6 | AD12: 1536 | AE12: 0.1 | AF12: 8
A13: 12 | B13: Final Stage 5 | C13: =K13&"/"&L13&"/"&M13&"/"&N13&"/"&TEXT(O13,"0.00")&"/"&P13 -> 12/128/4/2048/0.10/4 | D13: =S13&"/"&T13&"/"&U13&"/"&V13&"/"&TEXT(W13,"0.00")&"/"&X13 -> 10/192/6/2048/0.10/4 | E13: =AA13&"/"&AB13&"/"&AC13&"/"&AD13&"/"&TEXT(AE13,"0.00")&"/"&AF13 -> 8/256/8/2048/0.15/4 | J13: =(Step1_with_dropout!$P$2*L13+L13*N13+K13*(12*L13^2+13*L13)+L13*Step1_with_dropout!$P$2)/1000000 -> 2.688768 | K13: 12 | L13: 128 | M13: 4 | N13: 2048 | O13: 0.1 | P13: 4 | R13: =(Step1_with_dropout!$P$2*T13+T13*V13+S13*(12*T13^2+13*T13)+T13*Step1_with_dropout!$P$2)/1000000 -> 4.912896 | S13: 10 | T13: 192 | U13: 6 | V13: 2048 | W13: 0.1 | X13: 4 | Z13: =(Step1_with_dropout!$P$2*AB13+AB13*AD13+AA13*(12*AB13^2+13*AB13)+AB13*Step1_with_dropout!$P$2)/1000000 -> 6.937088 | AA13: 8 | AB13: 256 | AC13: 8 | AD13: 2048 | AE13: 0.15 | AF13: 4

Sheet Step3
A1: № | B1: iterations | C1: Params | D1: =D3&"/"&D4&"/"&D5&"/"&D6&"/"&TEXT(D7,"0.00")&"/"&D8 -> 12/128/4/2048/0.10/4 | F1: =F3&"/"&F4&"/"&F5&"/"&F6&"/"&TEXT(F7,"0.00")&"/"&F8 -> 10/192/6/2048/0.10/4 | H1: =H3&"/"&H4&"/"&H5&"/"&H6&"/"&TEXT(H7,"0.00")&"/"&H8 -> 8/256/8/2048/0.15/4 | J1: =J3&"/"&J4&"/"&J5&"/"&J6&"/"&TEXT(J7,"0.00")&"/"&J8 -> 12/128/4/2048/0.10/4 | L1: =L3&"/"&L4&"/"&L5&"/"&L6&"/"&TEXT(L7,"0.00")&"/"&L8 -> 10/192/6/2048/0.10/4 | N1: =N3&"/"&N4&"/"&N5&"/"&N6&"/"&TEXT(N7,"0.00")&"/"&N8 -> 8/256/8/2048/0.15/4
A2: 1 | C2: model size, M | D2: =($R$2*D4+D4*D6+D3*(12*D4^2+13*D4)+D4*$R$2)/1000000 -> 2.688768 | F2: =($R$2*F4+F4*F6+F3*(12*F4^2+13*F4)+F4*$R$2)/1000000 -> 4.912896 | H2: =($R$2*H4+H4*H6+H3*(12*H4^2+13*H4)+H4*$R$2)/1000000 -> 6.937088 | J2: =($R$2*J4+J4*J6+J3*(12*J4^2+13*J4)+J4*$R$2)/1000000 -> 2.688768 | L2: =($R$2*L4+L4*L6+L3*(12*L4^2+13*L4)+L4*$R$2)/1000000 -> 4.912896 | N2: =($R$2*N4+N4*N6+N3*(12*N4^2+13*N4)+N4*$R$2)/1000000 -> 6.937088 | Q2: vocab_size | R2: 185
A3: 2 | C3: n_layer | D3: 12 | F3: 10 | H3: 8 | J3: 12 | L3: 10 | N3: 8
A4: 3 | C4: n_embd | D4: 128 | F4: 192 | H4: 256 | J4: 128 | L4: 192 | N4: 256
A5: 4 | C5: n_head | D5: 4 | F5: 6 | H5: 8 | J5: 4 | L5: 6 | N5: 8
A6: 5 | C6: block_size | D6: 2048 | F6: 2048 | H6: 2048 | J6: 2048 | L6: 2048 | N6: 2048
A7: 6 | C7: dropout | D7: 0.1 | F7: 0.1 | H7: 0.15 | J7: 0.1 | L7: 0.1 | N7: 0.15
A8: 7 | C8: batch_size | D8: 4 | F8: 4 | H8: 4 | J8: 4 | L8: 4 | N8: 4
A9: 8 | C9: zero_new_weights | D9: True | F9: True | H9: True | J9: False | L9: False | N9: False
A10: 9 | B10: Stage 1 | C10: model | D10: =Step3_Models_plan!C9&"/"&D11/1000&"k" -> 2/32/1/128/0.00/64/80k | F10: =Step3_Models_plan!D9&"/"&F11/1000&"k" -> 2/64/2/128/0.00/64/80k | H10: =Step3_Models_plan!E9&"/"&H11/1000&"k" -> 2/64/2/128/0.00/64/80k | J10: =Step3_Models_plan!C9&"/"&J11/1000&"k" -> 2/32/1/128/0.00/64/80k | L10: =Step3_Models_plan!D9&"/"&L11/1000&"k" -> 2/64/2/128/0.00/64/80k | N10: =Step3_Models_plan!E9&"/"&N11/1000&"k" -> 2/64/2/128/0.00/64/80k
A11: 10 | C11: iterations | D11: 80000 | F11: 80000 | H11: 80000 | J11: 80000 | L11: 80000 | N11: 80000
A12: 11 | C12: duration / val/train | D12: 434 | E12: =D14/D13 -> 1.2828185 | F12: 437 | G12: =F14/F13 -> 1.5386187 | H12: 420 | I12: =H14/H13 -> 1.5386187 | J12: 432 | K12: =J14/J13 -> 1.2828185 | L12: 437 | M12: =L14/L13 -> 1.5386187 | N12: 445 | O12: =N14/N13 -> 1.5386187
A13: 12 | C13: train loss | D13: 1.5441 | F13: 1.2235 | H13: 1.2235 | J13: 1.5441 | L13: 1.2235 | N13: 1.2235
A14: 13 | C14: val loss | D14: 1.9808 | F14: 1.8825 | H14: 1.8825 | J14: 1.9808 | L14: 1.8825 | N14: 1.8825
A15: 14 | B15: Stage 2 | C15: model | D15: =Step3_Models_plan!C10&"/"&D16/1000&"k" -> 4/64/2/256/0.05/64/115k | F15: =Step3_Models_plan!D10&"/"&F16/1000&"k" -> 4/96/3/256/0.05/64/100k | H15: =Step3_Models_plan!E10&"/"&H16/1000&"k" -> 3/96/3/256/0.05/64/175k | J15: =Step3_Models_plan!C10&"/"&J16/1000&"k" -> 4/64/2/256/0.05/64/110k | L15: =Step3_Models_plan!D10&"/"&L16/1000&"k" -> 4/96/3/256/0.05/64/80k | N15: =Step3_Models_plan!E10&"/"&N16/1000&"k" -> 3/96/3/256/0.05/64/125k
A16: 15 | C16: iterations | D16: 115000 | F16: 100000 | H16: 175000 | J16: 110000 | L16: 80000 | N16: 125000
A17: 16 | C17: duration / val/train | D17: 1101 | E17: =D19/D18 -> 1.4515099 | F17: 1490 | G17: =F19/F18 -> 1.6929083 | H17: 2003 | I17: =H19/H18 -> 1.5810931 | J17: 1070 | K17: =J19/J18 -> 1.4681867 | L17: 1170 | M17: =L19/L18 -> 1.7865793 | N17: 1468 | O17: =N19/N18 -> 1.6229849
A18: 17 | C18: train loss | D18: 1.159 | E18: =(D18-D13)/D13 -> -0.24940095 | F18: 0.9222 | G18: =(F18-F13)/F13 -> -0.24626073 | H18: 1.0081 | I18: =(H18-H13)/H13 -> -0.17605231 | J18: 1.1096 | K18: =(J18-J13)/J13 -> -0.28139369 | L18: 0.9001 | M18: =(L18-L13)/L13 -> -0.26432366 | N18: 0.9615 | O18: =(N18-N13)/N13 -> -0.21413976
A19: 18 | C19: val loss | D19: 1.6823 | E19: =(D19-D14)/D14 -> -0.15069669 | F19: 1.5612 | G19: =(F19-F14)/F14 -> -0.17067729 | H19: 1.5939 | I19: =(H19-H14)/H14 -> -0.15330677 | J19: 1.6291 | K19: =(J19-J14)/J14 -> -0.17755452 | L19: 1.6081 | M19: =(L19-L14)/L14 -> -0.14576361 | N19: 1.5605 | O19: =(N19-N14)/N14 -> -0.17104914
A20: 19 | B20: Stage 3 | C20: model | D20: =Step3_Models_plan!C11&"/"&D21/1000&"k" -> 6/64/2/512/0.05/64/75k | F20: =Step3_Models_plan!D11&"/"&F21/1000&"k" -> 6/128/4/512/0.10/64/25k | H20: =Step3_Models_plan!E11&"/"&H21/1000&"k" -> 4/128/4/512/0.05/64/40k | J20: =Step3_Models_plan!C11&"/"&J21/1000&"k" -> 6/64/2/512/0.05/64/35k | L20: =Step3_Models_plan!D11&"/"&L21/1000&"k" -> 6/128/4/512/0.10/64/20k | N20: =Step3_Models_plan!E11&"/"&N21/1000&"k" -> 4/128/4/512/0.05/64/20k
A21: 20 | C21: iterations | D21: 75000 | F21: 25000 | H21: 40000 | J21: 35000 | L21: 20000 | N21: 20000
A22: 21 | C22: duration / val/train | D22: 3407 | E22: =D24/D23 -> 1.5426204 | F22: 2299 | G22: =F24/F23 -> 1.8021175 | H22: 2497 | I22: =H24/H23 -> 1.8215933 | J22: 1574 | K22: =J24/J23 -> 1.5140283 | L22: 1768 | M22: =L24/L23 -> 1.9384818 | N22: 1241 | O22: =N24/N23 -> 1.9330918
A23: 22 | C23: train loss | D23: 0.9655 | E23: =(D23-D18)/D18 -> -0.16695427 | F23: 0.7934 | G23: =(F23-F18)/F18 -> -0.13966602 | H23: 0.8021 | I23: =(H23-H18)/H18 -> -0.20434481 | J23: 0.9766 | K23: =(J23-J18)/J18 -> -0.11986301 | L23: 0.7575 | M23: =(L23-L18)/L18 -> -0.15842684 | N23: 0.7727 | O23: =(N23-N18)/N18 -> -0.19635985
A24: 23 | C24: val loss | D24: 1.4894 | E24: =(D24-D19)/D19 -> -0.11466445 | F24: 1.4298 | G24: =(F24-F19)/F19 -> -0.084166026 | H24: 1.4611 | I24: =(H24-H19)/H19 -> -0.083317649 | J24: 1.4786 | K24: =(J24-J19)/J19 -> -0.092382297 | L24: 1.4684 | M24: =(L24-L19)/L19 -> -0.086872707 | N24: 1.4937 | O24: =(N24-N19)/N19 -> -0.042806793
A25: 24 | B25: Stage 4 | C25: model | D25: =Step3_Models_plan!C12&"/"&D26/1000&"k" -> 9/96/3/1024/0.05/32/75k | F25: =Step3_Models_plan!D12&"/"&F26/1000&"k" -> 8/160/5/1536/0.10/8/95k | H25: =Step3_Models_plan!E12&"/"&H26/1000&"k" -> 6/192/6/1536/0.10/8/110k | J25: =Step3_Models_plan!C12&"/"&J26/1000&"k" -> 9/96/3/1024/0.05/32/95k | L25: =Step3_Models_plan!D12&"/"&L26/1000&"k" -> 8/160/5/1536/0.10/8/95k | N25: =Step3_Models_plan!E12&"/"&N26/1000&"k" -> 6/192/6/1536/0.10/8/85k
A26: 25 | C26: iterations | D26: 75000 | F26: 95000 | H26: 110000 | J26: 95000 | L26: 95000 | N26: 85000
A27: 26 | C27: duration / val/train | D27: 13334 | E27: =D29/D28 -> 1.6796958 | F27: 14050 | G27: =F29/F28 -> 1.9599681 | H27: 14644 | I27: =H29/H28 -> 1.9161905 | J27: 16583 | K27: =J29/J28 -> 1.9072211 | L27: 13995 | M27: =L29/L28 -> 2.2209551 | N27: 11269 | O27: =N29/N28 -> 2.2053978
A28: 27 | C28: train loss | D28: 0.7496 | E28: =(D28-D23)/D23 -> -0.22361471 | F28: 0.627 | G28: =(F28-F23)/F23 -> -0.20973027 | H28: 0.63 | I28: =(H28-H23)/H23 -> -0.21456178 | J28: 0.6758 | K28: =(J28-J23)/J23 -> -0.30800737 | L28: 0.5612 | M28: =(L28-L23)/L23 -> -0.25914191 | N28: 0.5706 | O28: =(N28-N23)/N23 -> -0.26155041
